Workbook

Sheet 總表
A1: 姓名 | B1: 所屬系所 | C1: 學號 | D1: W | E1: Lab01 | F1: Lab02 | G1: Lab03 | H1: Lab04 | I1: Lab05 | J1: Final Exam | K1: Final Project | L1: Total | M1: Grade
A2: 陳柏翔 | B2: 電子碩 / IEE | C2: 313510156 | D2: FALSE | E2: ='Lab01'!K45 -> 100 | F2: ='Lab02'!K45 -> 83 | G2: ='Lab03'!U46 -> 97 | H2: ='Lab04'!S46 -> 98 | I2: ='Lab05'!P46 -> 98.5 | J2: ='Final Exam'!W46 -> 88.5 | K2: ='Final Project'!H45 -> 99.9 | L2: =IF(D2=TRUE,0,(E2+F2+G2+H2+I2)*0.12+(J2+K2)*0.2) -> 94.86 | M2: =IF(D2=TRUE,"W",IF(L2>=89.4,"A+",IF(L2>=84.4,"A",IF(L2>=79.4,"A-",IF(L2>=76.4,"B+",IF(L2>=72.4,"B",IF(L2>=69.4,"B-",IF(L2>=66.4,"C+",IF(L2>=62.4,"C",IF(L2>=59.4,"C-",IF(L2>=49.4,"D",IF(L2>0,"E",IF(L2<=0,"X",""))))))))))))) -> A+
A3: 梁皓鈞 | B3: 前瞻半導體 / Pio-SEMI | C3: 314580042 | D3: FALSE | E3: ='Lab01'!K117 -> 91 | F3: ='Lab02'!K117 -> 89.75 | G3: ='Lab03'!U118 -> 98 | H3: ='Lab04'!S118 -> 93 | I3: ='Lab05'!P118 -> 99 | J3: ='Final Exam'!W118 -> 88.5 | K3: ='Final Project'!H117 -> 98 | L3: =IF(D3=TRUE,0,(E3+F3+G3+H3+I3)*0.12+(J3+K3)*0.2) -> 93.79 | M3: =IF(D3=TRUE,"W",IF(L3>=89.4,"A+",IF(L3>=84.4,"A",IF(L3>=79.4,"A-",IF(L3>=76.4,"B+",IF(L3>=72.4,"B",IF(L3>=69.4,"B-",IF(L3>=66.4,"C+",IF(L3>=62.4,"C",IF(L3>=59.4,"C-",IF(L3>=49.4,"D",IF(L3>0,"E",IF(L3<=0,"X",""))))))))))))) -> A+
A4: 李博安 | B4: 電子碩 / IEE | C4: 314510120 | D4: FALSE | E4: ='Lab01'!K78 -> 94 | F4: ='Lab02'!K78 -> 96 | G4: ='Lab03'!U79 -> 96 | H4: ='Lab04'!S79 -> 92 | I4: ='Lab05'!P79 -> 94.5 | J4: ='Final Exam'!W79 -> 85.5 | K4: ='Final Project'!H78 -> 94.4 | L4: =IF(D4=TRUE,0,(E4+F4+G4+H4+I4)*0.12+(J4+K4)*0.2) -> 92.68 | M4: =IF(D4=TRUE,"W",IF(L4>=89.4,"A+",IF(L4>=84.4,"A",IF(L4>=79.4,"A-",IF(L4>=76.4,"B+",IF(L4>=72.4,"B",IF(L4>=69.4,"B-",IF(L4>=66.4,"C+",IF(L4>=62.4,"C",IF(L4>=59.4,"C-",IF(L4>=49.4,"D",IF(L4>0,"E",IF(L4<=0,"X",""))))))))))))) -> A+
A5: 胡育豪 | B5: 人工智慧 / AIG | C5: 314505002 | D5: FALSE | E5: ='Lab01'!K64 -> 97 | F5: ='Lab02'!K64 -> 96.75 | G5: ='Lab03'!U65 -> 97 | H5: ='Lab04'!S65 -> 84 | I5: ='Lab05'!P65 -> 97.75 | J5: ='Final Exam'!W65 -> 81.5 | K5: ='Final Project'!H64 -> 91.8 | L5: =IF(D5=TRUE,0,(E5+F5+G5+H5+I5)*0.12+(J5+K5)*0.2) -> 91.36 | M5: =IF(D5=TRUE,"W",IF(L5>=89.4,"A+",IF(L5>=84.4,"A",IF(L5>=79.4,"A-",IF(L5>=76.4,"B+",IF(L5>=72.4,"B",IF(L5>=69.4,"B-",IF(L5>=66.4,"C+",IF(L5>=62.4,"C",IF(L5>=59.4,"C-",IF(L5>=49.4,"D",IF(L5>0,"E",IF(L5<=0,"X",""))))))))))))) -> A+
A6: 康鈞睿 | B6: 電子碩 / IEE | C6: 313510217 | D6: FALSE | E6: ='Lab01'!K53 -> 88 | F6: ='Lab02'!K53 -> 88.75 | G6: ='Lab03'!U54 -> 88 | H6: ='Lab04'!S54 -> 96 | I6: ='Lab05'!P54 -> 91.75 | J6: ='Final Exam'!W54 -> 82 | K6: ='Final Project'!H53 -> 99.9 | L6: =IF(D6=TRUE,0,(E6+F6+G6+H6+I6)*0.12+(J6+K6)*0.2) -> 90.68 | M6: =IF(D6=TRUE,"W",IF(L6>=89.4,"A+",IF(L6>=84.4,"A",IF(L6>=79.4,"A-",IF(L6>=76.4,"B+",IF(L6>=72.4,"B",IF(L6>=69.4,"B-",IF(L6>=66.4,"C+",IF(L6>=62.4,"C",IF(L6>=59.4,"C-",IF(L6>=49.4,"D",IF(L6>0,"E",IF(L6<=0,"X",""))))))))))))) -> A+
A7: 李崇碩 | B7: 電子碩 / IEE | C7: 313510230 | D7: FALSE | E7: ='Lab01'!K54 -> 96 | F7: ='Lab02'!K54 -> 92.25 | G7: ='Lab03'!U55 -> 92 | H7: ='Lab04'!S55 -> 97 | I7: ='Lab05'!P55 -> 94.75 | J7: ='Final Exam'!W55 -> 77.5 | K7: ='Final Project'!H54 -> 91.8 | L7: =IF(D7=TRUE,0,(E7+F7+G7+H7+I7)*0.12+(J7+K7)*0.2) -> 90.5 | M7: =IF(D7=TRUE,"W",IF(L7>=89.4,"A+",IF(L7>=84.4,"A",IF(L7>=79.4,"A-",IF(L7>=76.4,"B+",IF(L7>=72.4,"B",IF(L7>=69.4,"B-",IF(L7>=66.4,"C+",IF(L7>=62.4,"C",IF(L7>=59.4,"C-",IF(L7>=49.4,"D",IF(L7>0,"E",IF(L7<=0,"X",""))))))))))))) -> A+
A8: 李昱承 | B8: 電機系 / UEE | C8: 111511249 | D8: FALSE | E8: ='Lab01'!K20 -> 95 | F8: ='Lab02'!K20 -> 79.5 | G8: ='Lab03'!U21 -> 95 | H8: ='Lab04'!S21 -> 93 | I8: ='Lab05'!P21 -> 88.75 | J8: ='Final Exam'!W21 -> 83 | K8: ='Final Project'!H20 -> 97.6 | L8: =IF(D8=TRUE,0,(E8+F8+G8+H8+I8)*0.12+(J8+K8)*0.2) -> 90.27 | M8: =IF(D8=TRUE,"W",IF(L8>=89.4,"A+",IF(L8>=84.4,"A",IF(L8>=79.4,"A-",IF(L8>=76.4,"B+",IF(L8>=72.4,"B",IF(L8>=69.4,"B-",IF(L8>=66.4,"C+",IF(L8>=62.4,"C",IF(L8>=59.4,"C-",IF(L8>=49.4,"D",IF(L8>0,"E",IF(L8<=0,"X",""))))))))))))) -> A+
A9: 張語楹 | B9: 電子碩 / IEE | C9: 314510126 | D9: FALSE | E9: ='Lab01'!K80 -> 92 | F9: ='Lab02'!K80 -> 88.75 | G9: ='Lab03'!U81 -> 84 | H9: ='Lab04'!S81 -> 86 | I9: ='Lab05'!P81 -> 94 | J9: ='Final Exam'!W81 -> 84.5 | K9: ='Final Project'!H80 -> 97.3 | L9: =IF(D9=TRUE,0,(E9+F9+G9+H9+I9)*0.12+(J9+K9)*0.2) -> 89.73 | M9: =IF(D9=TRUE,"W",IF(L9>=89.4,"A+",IF(L9>=84.4,"A",IF(L9>=79.4,"A-",IF(L9>=76.4,"B+",IF(L9>=72.4,"B",IF(L9>=69.4,"B-",IF(L9>=66.4,"C+",IF(L9>=62.4,"C",IF(L9>=59.4,"C-",IF(L9>=49.4,"D",IF(L9>0,"E",IF(L9<=0,"X",""))))))))))))) -> A+
A10: 劉昱旻 | B10: 電子碩 / IEE | C10: 314510166 | D10: FALSE | E10: ='Lab01'!K91 -> 97 | F10: ='Lab02'!K91 -> 85.5 | G10: ='Lab03'!U92 -> 87 | H10: ='Lab04'!S92 -> 94 | I10: ='Lab05'!P92 -> 94 | J10: ='Final Exam'!W92 -> 75.5 | K10: ='Final Project'!H91 -> 97.3 | L10: =IF(D10=TRUE,0,(E10+F10+G10+H10+I10)*0.12+(J10+K10)*0.2) -> 89.46 | M10: =IF(D10=TRUE,"W",IF(L10>=89.4,"A+",IF(L10>=84.4,"A",IF(L10>=79.4,"A-",IF(L10>=76.4,"B+",IF(L10>=72.4,"B",IF(L10>=69.4,"B-",IF(L10>=66.4,"C+",IF(L10>=62.4,"C",IF(L10>=59.4,"C-",IF(L10>=49.4,"D",IF(L10>0,"E",IF(L10<=0,"X",""))))))))))))) -> A+
A11: 林后辰 | B11: 電機系 / UEE | C11: 111511009 | D11: FALSE | E11: ='Lab01'!K6 -> 97 | F11: ='Lab02'!K6 -> 97 | G11: ='Lab03'!U7 -> 90 | H11: ='Lab04'!S7 -> 93 | I11: ='Lab05'!P7 -> 76.25 | J11: ='Final Exam'!W7 -> 82 | K11: ='Final Project'!H6 -> 93.1 | L11: =IF(D11=TRUE,0,(E11+F11+G11+H11+I11)*0.12+(J11+K11)*0.2) -> 89.41 | M11: =IF(D11=TRUE,"W",IF(L11>=89.4,"A+",IF(L11>=84.4,"A",IF(L11>=79.4,"A-",IF(L11>=76.4,"B+",IF(L11>=72.4,"B",IF(L11>=69.4,"B-",IF(L11>=66.4,"C+",IF(L11>=62.4,"C",IF(L11>=59.4,"C-",IF(L11>=49.4,"D",IF(L11>0,"E",IF(L11<=0,"X",""))))))))))))) -> A+
A12: 賴柏任 | B12: 電機系 / UEE | C12: 111511211 | D12: FALSE | E12: ='Lab01'!K17 -> 96 | F12: ='Lab02'!K17 -> 91.5 | G12: ='Lab03'!U18 -> 88 | H12: ='Lab04'!S18 -> 85 | I12: ='Lab05'!P18 -> 84 | J12: ='Final Exam'!W18 -> 86.5 | K12: ='Final Project'!H17 -> 93.3 | L12: =IF(D12=TRUE,0,(E12+F12+G12+H12+I12)*0.12+(J12+K12)*0.2) -> 89.3 | M12: =IF(D12=TRUE,"W",IF(L12>=89.4,"A+",IF(L12>=84.4,"A",IF(L12>=79.4,"A-",IF(L12>=76.4,"B+",IF(L12>=72.4,"B",IF(L12>=69.4,"B-",IF(L12>=66.4,"C+",IF(L12>=62.4,"C",IF(L12>=59.4,"C-",IF(L12>=49.4,"D",IF(L12>0,"E",IF(L12<=0,"X",""))))))))))))) -> A
A13: 林柏伸 | B13: 電機系 / UEE | C13: 111611088 | D13: FALSE | E13: ='Lab01'!K29 -> 90 | F13: ='Lab02'!K29 -> 93.75 | G13: ='Lab03'!U30 -> 90 | H13: ='Lab04'!S30 -> 88 | I13: ='Lab05'!P30 -> 92.5 | J13: ='Final Exam'!W30 -> 78 | K13: ='Final Project'!H29 -> 95.5 | L13: =IF(D13=TRUE,0,(E13+F13+G13+H13+I13)*0.12+(J13+K13)*0.2) -> 89.21 | M13: =IF(D13=TRUE,"W",IF(L13>=89.4,"A+",IF(L13>=84.4,"A",IF(L13>=79.4,"A-",IF(L13>=76.4,"B+",IF(L13>=72.4,"B",IF(L13>=69.4,"B-",IF(L13>=66.4,"C+",IF(L13>=62.4,"C",IF(L13>=59.4,"C-",IF(L13>=49.4,"D",IF(L13>0,"E",IF(L13<=0,"X",""))))))))))))) -> A
A14: 鍾宗揚 | B14: 電機系 / UEE | C14: 111511186 | D14: FALSE | E14: ='Lab01'!K15 -> 90 | F14: ='Lab02'!K15 -> 85 | G14: ='Lab03'!U16 -> 95 | H14: ='Lab04'!S16 -> 85 | I14: ='Lab05'!P16 -> 89.25 | J14: ='Final Exam'!W16 -> 82 | K14: ='Final Project'!H15 -> 95.5 | L14: =IF(D14=TRUE,0,(E14+F14+G14+H14+I14)*0.12+(J14+K14)*0.2) -> 88.81 | M14: =IF(D14=TRUE,"W",IF(L14>=89.4,"A+",IF(L14>=84.4,"A",IF(L14>=79.4,"A-",IF(L14>=76.4,"B+",IF(L14>=72.4,"B",IF(L14>=69.4,"B-",IF(L14>=66.4,"C+",IF(L14>=62.4,"C",IF(L14>=59.4,"C-",IF(L14>=49.4,"D",IF(L14>0,"E",IF(L14<=0,"X",""))))))))))))) -> A
A15: 徐煜絨 | B15: 電子碩 / IEE | C15: 314510152 | D15: FALSE | E15: ='Lab01'!K88 -> 92 | F15: ='Lab02'!K88 -> 92 | G15: ='Lab03'!U89 -> 91 | H15: ='Lab04'!S89 -> 90 | I15: ='Lab05'!P89 -> 92.75 | J15: ='Final Exam'!W89 -> 80.5 | K15: ='Final Project'!H88 -> 87.8 | L15: =IF(D15=TRUE,0,(E15+F15+G15+H15+I15)*0.12+(J15+K15)*0.2) -> 88.59 | M15: =IF(D15=TRUE,"W",IF(L15>=89.4,"A+",IF(L15>=84.4,"A",IF(L15>=79.4,"A-",IF(L15>=76.4,"B+",IF(L15>=72.4,"B",IF(L15>=69.4,"B-",IF(L15>=66.4,"C+",IF(L15>=62.4,"C",IF(L15>=59.4,"C-",IF(L15>=49.4,"D",IF(L15>0,"E",IF(L15<=0,"X",""))))))))))))) -> A
A16: 許立勛 | B16: 前瞻半導體 / Pio-SEMI | C16: 314580044 | D16: FALSE | E16: ='Lab01'!K118 -> 90 | F16: ='Lab02'!K118 -> 84.25 | G16: ='Lab03'!U119 -> 93 | H16: ='Lab04'!S119 -> 94 | I16: ='Lab05'!P119 -> 92.25 | J16: ='Final Exam'!W119 -> 76 | K16: ='Final Project'!H118 -> 93.7 | L16: =IF(D16=TRUE,0,(E16+F16+G16+H16+I16)*0.12+(J16+K16)*0.2) -> 88.36 | M16: =IF(D16=TRUE,"W",IF(L16>=89.4,"A+",IF(L16>=84.4,"A",IF(L16>=79.4,"A-",IF(L16>=76.4,"B+",IF(L16>=72.4,"B",IF(L16>=69.4,"B-",IF(L16>=66.4,"C+",IF(L16>=62.4,"C",IF(L16>=59.4,"C-",IF(L16>=49.4,"D",IF(L16>0,"E",IF(L16<=0,"X",""))))))))))))) -> A
A17: 麥祐嘉 | B17: 電子碩 / IEE | C17: 314510134 | D17: FALSE | E17: ='Lab01'!K84 -> 89 | F17: ='Lab02'!K84 -> 91.75 | G17: ='Lab03'!U85 -> 93 | H17: ='Lab04'!S85 -> 89 | I17: ='Lab05'!P85 -> 88 | J17: ='Final Exam'!W85 -> 79 | K17: ='Final Project'!H84 -> 90.8 | L17: =IF(D17=TRUE,0,(E17+F17+G17+H17+I17)*0.12+(J17+K17)*0.2) -> 88.05 | M17: =IF(D17=TRUE,"W",IF(L17>=89.4,"A+",IF(L17>=84.4,"A",IF(L17>=79.4,"A-",IF(L17>=76.4,"B+",IF(L17>=72.4,"B",IF(L17>=69.4,"B-",IF(L17>=66.4,"C+",IF(L17>=62.4,"C",IF(L17>=59.4,"C-",IF(L17>=49.4,"D",IF(L17>0,"E",IF(L17<=0,"X",""))))))))))))) -> A
A18: 黃治鈞 | B18: 電機系 / UEE | C18: 111511306 | D18: FALSE | E18: ='Lab01'!K25 -> 96 | F18: ='Lab02'!K25 -> 88 | G18: ='Lab03'!U26 -> 85 | H18: ='Lab04'!S26 -> 80 | I18: ='Lab05'!P26 -> 82 | J18: ='Final Exam'!W26 -> 85 | K18: ='Final Project'!H25 -> 95.3 | L18: =IF(D18=TRUE,0,(E18+F18+G18+H18+I18)*0.12+(J18+K18)*0.2) -> 87.78 | M18: =IF(D18=TRUE,"W",IF(L18>=89.4,"A+",IF(L18>=84.4,"A",IF(L18>=79.4,"A-",IF(L18>=76.4,"B+",IF(L18>=72.4,"B",IF(L18>=69.4,"B-",IF(L18>=66.4,"C+",IF(L18>=62.4,"C",IF(L18>=59.4,"C-",IF(L18>=49.4,"D",IF(L18>0,"E",IF(L18<=0,"X",""))))))))))))) -> A
A19: 薛天其 | B19: 電機系 / UEE | C19: 111610032 | D19: FALSE | E19: ='Lab01'!K28 -> 92 | F19: ='Lab02'!K28 -> 88.5 | G19: ='Lab03'!U29 -> 93 | H19: ='Lab04'!S29 -> 85 | I19: ='Lab05'!P29 -> 92.5 | J19: ='Final Exam'!W29 -> 77 | K19: ='Final Project'!H28 -> 90 | L19: =IF(D19=TRUE,0,(E19+F19+G19+H19+I19)*0.12+(J19+K19)*0.2) -> 87.52 | M19: =IF(D19=TRUE,"W",IF(L19>=89.4,"A+",IF(L19>=84.4,"A",IF(L19>=79.4,"A-",IF(L19>=76.4,"B+",IF(L19>=72.4,"B",IF(L19>=69.4,"B-",IF(L19>=66.4,"C+",IF(L19>=62.4,"C",IF(L19>=59.4,"C-",IF(L19>=49.4,"D",IF(L19>0,"E",IF(L19<=0,"X",""))))))))))))) -> A
A20: 王睿哲 | B20: 電子碩 / IEE | C20: 313510214 | D20: FALSE | E20: ='Lab01'!K52 -> 91 | F20: ='Lab02'!K52 -> 91 | G20: ='Lab03'!U53 -> 98 | H20: ='Lab04'!S53 -> 92 | I20: ='Lab05'!P53 -> 86 | J20: ='Final Exam'!W53 -> 71.5 | K20: ='Final Project'!H52 -> 90.4 | L20: =IF(D20=TRUE,0,(E20+F20+G20+H20+I20)*0.12+(J20+K20)*0.2) -> 87.34 | M20: =IF(D20=TRUE,"W",IF(L20>=89.4,"A+",IF(L20>=84.4,"A",IF(L20>=79.4,"A-",IF(L20>=76.4,"B+",IF(L20>=72.4,"B",IF(L20>=69.4,"B-",IF(L20>=66.4,"C+",IF(L20>=62.4,"C",IF(L20>=59.4,"C-",IF(L20>=49.4,"D",IF(L20>0,"E",IF(L20<=0,"X",""))))))))))))) -> A
A21: 王乙棠 | B21: 電機系 / UEE | C21: 111511240 | D21: FALSE | E21: ='Lab01'!K18 -> 94 | F21: ='Lab02'!K18 -> 85.75 | G21: ='Lab03'!U19 -> 89 | H21: ='Lab04'!S19 -> 92 | I21: ='Lab05'!P19 -> 88.5 | J21: ='Final Exam'!W19 -> 72.5 | K21: ='Final Project'!H18 -> 94.6 | L21: =IF(D21=TRUE,0,(E21+F21+G21+H21+I21)*0.12+(J21+K21)*0.2) -> 87.33 | M21: =IF(D21=TRUE,"W",IF(L21>=89.4,"A+",IF(L21>=84.4,"A",IF(L21>=79.4,"A-",IF(L21>=76.4,"B+",IF(L21>=72.4,"B",IF(L21>=69.4,"B-",IF(L21>=66.4,"C+",IF(L21>=62.4,"C",IF(L21>=59.4,"C-",IF(L21>=49.4,"D",IF(L21>0,"E",IF(L21<=0,"X",""))))))))))))) -> A
A22: 徐瑞澤 | B22: 電子碩 / IEE | C22: 314510195 | D22: FALSE | E22: ='Lab01'!K98 -> 88 | F22: ='Lab02'!K98 -> 91.5 | G22: ='Lab03'!U99 -> 79 | H22: ='Lab04'!S99 -> 88 | I22: ='Lab05'!P99 -> 89.25 | J22: ='Final Exam'!W99 -> 80 | K22: ='Final Project'!H98 -> 93.7 | L22: =IF(D22=TRUE,0,(E22+F22+G22+H22+I22)*0.12+(J22+K22)*0.2) -> 87.03 | M22: =IF(D22=TRUE,"W",IF(L22>=89.4,"A+",IF(L22>=84.4,"A",IF(L22>=79.4,"A-",IF(L22>=76.4,"B+",IF(L22>=72.4,"B",IF(L22>=69.4,"B-",IF(L22>=66.4,"C+",IF(L22>=62.4,"C",IF(L22>=59.4,"C-",IF(L22>=49.4,"D",IF(L22>0,"E",IF(L22<=0,"X",""))))))))))))) -> A
A23: 白勝全 | B23: 電子碩 / IEE | C23: 314510209 | D23: FALSE | E23: ='Lab01'!K103 -> 97 | F23: ='Lab02'!K103 -> 91 | G23: ='Lab03'!U104 -> 94 | H23: ='Lab04'!S104 -> 86 | I23: ='Lab05'!P104 -> 72.25 | J23: ='Final Exam'!W104 -> 76 | K23: ='Final Project'!H103 -> 94.6 | L23: =IF(D23=TRUE,0,(E23+F23+G23+H23+I23)*0.12+(J23+K23)*0.2) -> 86.95 | M23: =IF(D23=TRUE,"W",IF(L23>=89.4,"A+",IF(L23>=84.4,"A",IF(L23>=79.4,"A-",IF(L23>=76.4,"B+",IF(L23>=72.4,"B",IF(L23>=69.4,"B-",IF(L23>=66.4,"C+",IF(L23>=62.4,"C",IF(L23>=59.4,"C-",IF(L23>=49.4,"D",IF(L23>0,"E",IF(L23<=0,"X",""))))))))))))) -> A
A24: 鐘邦郡 | B24: 資工系 / DCP | C24: 111652031 | D24: FALSE | E24: ='Lab01'!K31 -> 88 | F24: ='Lab02'!K31 -> 92.5 | G24: ='Lab03'!U32 -> 71 | H24: ='Lab04'!S32 -> 86 | I24: ='Lab05'!P32 -> 89.25 | J24: ='Final Exam'!W32 -> 84 | K24: ='Final Project'!H31 -> 93.3 | L24: =IF(D24=TRUE,0,(E24+F24+G24+H24+I24)*0.12+(J24+K24)*0.2) -> 86.67 | M24: =IF(D24=TRUE,"W",IF(L24>=89.4,"A+",IF(L24>=84.4,"A",IF(L24>=79.4,"A-",IF(L24>=76.4,"B+",IF(L24>=72.4,"B",IF(L24>=69.4,"B-",IF(L24>=66.4,"C+",IF(L24>=62.4,"C",IF(L24>=59.4,"C-",IF(L24>=49.4,"D",IF(L24>0,"E",IF(L24<=0,"X",""))))))))))))) -> A
A25: 任晏廷 | B25: 電子碩 / IEE | C25: 314510202 | D25: FALSE | E25: ='Lab01'!K102 -> 92 | F25: ='Lab02'!K102 -> 80.5 | G25: ='Lab03'!U103 -> 87 | H25: ='Lab04'!S103 -> 91 | I25: ='Lab05'!P103 -> 100 | J25: ='Final Exam'!W103 -> 74.5 | K25: ='Final Project'!H102 -> 88.1 | L25: =IF(D25=TRUE,0,(E25+F25+G25+H25+I25)*0.12+(J25+K25)*0.2) -> 86.58 | M25: =IF(D25=TRUE,"W",IF(L25>=89.4,"A+",IF(L25>=84.4,"A",IF(L25>=79.4,"A-",IF(L25>=76.4,"B+",IF(L25>=72.4,"B",IF(L25>=69.4,"B-",IF(L25>=66.4,"C+",IF(L25>=62.4,"C",IF(L25>=59.4,"C-",IF(L25>=49.4,"D",IF(L25>0,"E",IF(L25<=0,"X",""))))))))))))) -> A
A26: 李宇翔 | B26: 電機系 / UEE | C26: 111511247 | D26: FALSE | E26: ='Lab01'!K19 -> 97 | F26: ='Lab02'!K19 -> 89.75 | G26: ='Lab03'!U20 -> 86 | H26: ='Lab04'!S20 -> 91 | I26: ='Lab05'!P20 -> 76.5 | J26: ='Final Exam'!W20 -> 71 | K26: ='Final Project'!H19 -> 97.6 | L26: =IF(D26=TRUE,0,(E26+F26+G26+H26+I26)*0.12+(J26+K26)*0.2) -> 86.55 | M26: =IF(D26=TRUE,"W",IF(L26>=89.4,"A+",IF(L26>=84.4,"A",IF(L26>=79.4,"A-",IF(L26>=76.4,"B+",IF(L26>=72.4,"B",IF(L26>=69.4,"B-",IF(L26>=66.4,"C+",IF(L26>=62.4,"C",IF(L26>=59.4,"C-",IF(L26>=49.4,"D",IF(L26>0,"E",IF(L26<=0,"X",""))))))))))))) -> A
A27: 蔡東宏 | B27: 電子碩 / IEE | C27: 314510123 | D27: FALSE | E27: ='Lab01'!K79 -> 91 | F27: ='Lab02'!K79 -> 87.5 | G27: ='Lab03'!U80 -> 94 | H27: ='Lab04'!S80 -> 91 | I27: ='Lab05'!P80 -> 85.5 | J27: ='Final Exam'!W80 -> 69.5 | K27: ='Final Project'!H79 -> 93.3 | L27: =IF(D27=TRUE,0,(E27+F27+G27+H27+I27)*0.12+(J27+K27)*0.2) -> 86.44 | M27: =IF(D27=TRUE,"W",IF(L27>=89.4,"A+",IF(L27>=84.4,"A",IF(L27>=79.4,"A-",IF(L27>=76.4,"B+",IF(L27>=72.4,"B",IF(L27>=69.4,"B-",IF(L27>=66.4,"C+",IF(L27>=62.4,"C",IF(L27>=59.4,"C-",IF(L27>=49.4,"D",IF(L27>0,"E",IF(L27<=0,"X",""))))))))))))) -> A
A28: 莊之睿 | B28: 電機系 / UEE | C28: 111511010 | D28: FALSE | E28: ='Lab01'!K7 -> 91 | F28: ='Lab02'!K7 -> 92.25 | G28: ='Lab03'!U8 -> 84 | H28: ='Lab04'!S8 -> 91 | I28: ='Lab05'!P8 -> 64.25 | J28: ='Final Exam'!W8 -> 85.5 | K28: ='Final Project'!H7 -> 93.1 | L28: =IF(D28=TRUE,0,(E28+F28+G28+H28+I28)*0.12+(J28+K28)*0.2) -> 86.42 | M28: =IF(D28=TRUE,"W",IF(L28>=89.4,"A+",IF(L28>=84.4,"A",IF(L28>=79.4,"A-",IF(L28>=76.4,"B+",IF(L28>=72.4,"B",IF(L28>=69.4,"B-",IF(L28>=66.4,"C+",IF(L28>=62.4,"C",IF(L28>=59.4,"C-",IF(L28>=49.4,"D",IF(L28>0,"E",IF(L28<=0,"X",""))))))))))))) -> A
A29: 余姿燕 | B29: 電子碩 / IEE | C29: 313510159 | D29: FALSE | E29: ='Lab01'!K46 -> 88 | F29: ='Lab02'!K46 -> 94.75 | G29: ='Lab03'!U47 -> 90 | H29: ='Lab04'!S47 -> 90 | I29: ='Lab05'!P47 -> 86.75 | J29: ='Final Exam'!W47 -> 75.5 | K29: ='Final Project'!H46 -> 86.7 | L29: =IF(D29=TRUE,0,(E29+F29+G29+H29+I29)*0.12+(J29+K29)*0.2) -> 86.38 | M29: =IF(D29=TRUE,"W",IF(L29>=89.4,"A+",IF(L29>=84.4,"A",IF(L29>=79.4,"A-",IF(L29>=76.4,"B+",IF(L29>=72.4,"B",IF(L29>=69.4,"B-",IF(L29>=66.4,"C+",IF(L29>=62.4,"C",IF(L29>=59.4,"C-",IF(L29>=49.4,"D",IF(L29>0,"E",IF(L29<=0,"X",""))))))))))))) -> A
A30: 鄭人傑 | B30: 電子碩 / IEE | C30: 313510245 | D30: FALSE | E30: ='Lab01'!K58 -> 94 | F30: ='Lab02'!K58 -> 81.75 | G30: ='Lab03'!U59 -> 99 | H30: ='Lab04'!S59 -> 87 | I30: ='Lab05'!P59 -> 92.75 | J30: ='Final Exam'!W59 -> 70 | K30: ='Final Project'!H58 -> 88.1 | L30: =IF(D30=TRUE,0,(E30+F30+G30+H30+I30)*0.12+(J30+K30)*0.2) -> 86.16 | M30: =IF(D30=TRUE,"W",IF(L30>=89.4,"A+",IF(L30>=84.4,"A",IF(L30>=79.4,"A-",IF(L30>=76.4,"B+",IF(L30>=72.4,"B",IF(L30>=69.4,"B-",IF(L30>=66.4,"C+",IF(L30>=62.4,"C",IF(L30>=59.4,"C-",IF(L30>=49.4,"D",IF(L30>0,"E",IF(L30<=0,"X",""))))))))))))) -> A
A31: 簡宗弘 | B31: 電機系 / UEE | C31: 111511093 | D31: FALSE | E31: ='Lab01'!K10 -> 86 | F31: ='Lab02'!K10 -> 89.25 | G31: ='Lab03'!U11 -> 95 | H31: ='Lab04'!S11 -> 91 | I31: ='Lab05'!P11 -> 70.75 | J31: ='Final Exam'!W11 -> 73.5 | K31: ='Final Project'!H10 -> 98 | L31: =IF(D31=TRUE,0,(E31+F31+G31+H31+I31)*0.12+(J31+K31)*0.2) -> 86.14 | M31: =IF(D31=TRUE,"W",IF(L31>=89.4,"A+",IF(L31>=84.4,"A",IF(L31>=79.4,"A-",IF(L31>=76.4,"B+",IF(L31>=72.4,"B",IF(L31>=69.4,"B-",IF(L31>=66.4,"C+",IF(L31>=62.4,"C",IF(L31>=59.4,"C-",IF(L31>=49.4,"D",IF(L31>0,"E",IF(L31<=0,"X",""))))))))))))) -> A
A32: 鄭元閔 | B32: 電子碩 / IEE | C32: 314510151 | D32: FALSE | E32: ='Lab01'!K87 -> 91 | F32: ='Lab02'!K87 -> 90.75 | G32: ='Lab03'!U88 -> 92 | H32: ='Lab04'!S88 -> 86 | I32: ='Lab05'!P88 -> 89 | J32: ='Final Exam'!W88 -> 71.5 | K32: ='Final Project'!H87 -> 89.9 | L32: =IF(D32=TRUE,0,(E32+F32+G32+H32+I32)*0.12+(J32+K32)*0.2) -> 86.13 | M32: =IF(D32=TRUE,"W",IF(L32>=89.4,"A+",IF(L32>=84.4,"A",IF(L32>=79.4,"A-",IF(L32>=76.4,"B+",IF(L32>=72.4,"B",IF(L32>=69.4,"B-",IF(L32>=66.4,"C+",IF(L32>=62.4,"C",IF(L32>=59.4,"C-",IF(L32>=49.4,"D",IF(L32>0,"E",IF(L32<=0,"X",""))))))))))))) -> A
A33: 余家佑 | B33: 電子碩 / IEE | C33: 314510133 | D33: FALSE | E33: ='Lab01'!K83 -> 94 | F33: ='Lab02'!K83 -> 88.5 | G33: ='Lab03'!U84 -> 93 | H33: ='Lab04'!S84 -> 82 | I33: ='Lab05'!P84 -> 91.5 | J33: ='Final Exam'!W84 -> 72 | K33: ='Final Project'!H83 -> 88.1 | L33: =IF(D33=TRUE,0,(E33+F33+G33+H33+I33)*0.12+(J33+K33)*0.2) -> 85.9 | M33: =IF(D33=TRUE,"W",IF(L33>=89.4,"A+",IF(L33>=84.4,"A",IF(L33>=79.4,"A-",IF(L33>=76.4,"B+",IF(L33>=72.4,"B",IF(L33>=69.4,"B-",IF(L33>=66.4,"C+",IF(L33>=62.4,"C",IF(L33>=59.4,"C-",IF(L33>=49.4,"D",IF(L33>0,"E",IF(L33<=0,"X",""))))))))))))) -> A
A34: 鄭文碩 | B34: 電子碩 / IEE | C34: 314510173 | D34: FALSE | E34: ='Lab01'!K92 -> 90 | F34: ='Lab02'!K92 -> 84.5 | G34: ='Lab03'!U93 -> 88 | H34: ='Lab04'!S93 -> 80 | I34: ='Lab05'!P93 -> 81.5 | J34: ='Final Exam'!W93 -> 80.5 | K34: ='Final Project'!H92 -> 94.6 | L34: =IF(D34=TRUE,0,(E34+F34+G34+H34+I34)*0.12+(J34+K34)*0.2) -> 85.9 | M34: =IF(D34=TRUE,"W",IF(L34>=89.4,"A+",IF(L34>=84.4,"A",IF(L34>=79.4,"A-",IF(L34>=76.4,"B+",IF(L34>=72.4,"B",IF(L34>=69.4,"B-",IF(L34>=66.4,"C+",IF(L34>=62.4,"C",IF(L34>=59.4,"C-",IF(L34>=49.4,"D",IF(L34>0,"E",IF(L34<=0,"X",""))))))))))))) -> A
A35: 王信諺 | B35: 電機系 / UEE | C35: 111511260 | D35: FALSE | E35: ='Lab01'!K22 -> 94 | F35: ='Lab02'!K22 -> 89.5 | G35: ='Lab03'!U23 -> 80 | H35: ='Lab04'!S23 -> 93 | I35: ='Lab05'!P23 -> 81.5 | J35: ='Final Exam'!W23 -> 73 | K35: ='Final Project'!H22 -> 92.7 | L35: =IF(D35=TRUE,0,(E35+F35+G35+H35+I35)*0.12+(J35+K35)*0.2) -> 85.7 | M35: =IF(D35=TRUE,"W",IF(L35>=89.4,"A+",IF(L35>=84.4,"A",IF(L35>=79.4,"A-",IF(L35>=76.4,"B+",IF(L35>=72.4,"B",IF(L35>=69.4,"B-",IF(L35>=66.4,"C+",IF(L35>=62.4,"C",IF(L35>=59.4,"C-",IF(L35>=49.4,"D",IF(L35>0,"E",IF(L35<=0,"X",""))))))))))))) -> A
A36: 梁文熏 | B36: 前瞻半導體 / Pio-SEMI | C36: 314580048 | D36: FALSE | E36: ='Lab01'!K119 -> 93 | F36: ='Lab02'!K119 -> 88.25 | G36: ='Lab03'!U120 -> 99 | H36: ='Lab04'!S120 -> 88 | I36: ='Lab05'!P120 -> 91 | J36: ='Final Exam'!W120 -> 62.5 | K36: ='Final Project'!H119 -> 88.2 | L36: =IF(D36=TRUE,0,(E36+F36+G36+H36+I36)*0.12+(J36+K36)*0.2) -> 85.25 | M36: =IF(D36=TRUE,"W",IF(L36>=89.4,"A+",IF(L36>=84.4,"A",IF(L36>=79.4,"A-",IF(L36>=76.4,"B+",IF(L36>=72.4,"B",IF(L36>=69.4,"B-",IF(L36>=66.4,"C+",IF(L36>=62.4,"C",IF(L36>=59.4,"C-",IF(L36>=49.4,"D",IF(L36>0,"E",IF(L36<=0,"X",""))))))))))))) -> A
A37: 蔡綸鎧 | B37: 電子碩 / IEE | C37: 314510044 | D37: FALSE | E37: ='Lab01'!K72 -> 94 | F37: ='Lab02'!K72 -> 78.5 | G37: ='Lab03'!U73 -> 99 | H37: ='Lab04'!S73 -> 91 | I37: ='Lab05'!P73 -> 89.25 | J37: ='Final Exam'!W73 -> 60 | K37: ='Final Project'!H72 -> 95 | L37: =IF(D37=TRUE,0,(E37+F37+G37+H37+I37)*0.12+(J37+K37)*0.2) -> 85.21 | M37: =IF(D37=TRUE,"W",IF(L37>=89.4,"A+",IF(L37>=84.4,"A",IF(L37>=79.4,"A-",IF(L37>=76.4,"B+",IF(L37>=72.4,"B",IF(L37>=69.4,"B-",IF(L37>=66.4,"C+",IF(L37>=62.4,"C",IF(L37>=59.4,"C-",IF(L37>=49.4,"D",IF(L37>0,"E",IF(L37<=0,"X",""))))))))))))) -> A
A38: 陳昇達 | B38: 電子碩 / IEE | C38: 314510224 | D38: FALSE | E38: ='Lab01'!K107 -> 88 | F38: ='Lab02'!K107 -> 85.25 | G38: ='Lab03'!U108 -> 88 | H38: ='Lab04'!S108 -> 85 | I38: ='Lab05'!P108 -> 88.75 | J38: ='Final Exam'!W108 -> 71 | K38: ='Final Project'!H107 -> 93.7 | L38: =IF(D38=TRUE,0,(E38+F38+G38+H38+I38)*0.12+(J38+K38)*0.2) -> 85.14 | M38: =IF(D38=TRUE,"W",IF(L38>=89.4,"A+",IF(L38>=84.4,"A",IF(L38>=79.4,"A-",IF(L38>=76.4,"B+",IF(L38>=72.4,"B",IF(L38>=69.4,"B-",IF(L38>=66.4,"C+",IF(L38>=62.4,"C",IF(L38>=59.4,"C-",IF(L38>=49.4,"D",IF(L38>0,"E",IF(L38<=0,"X",""))))))))))))) -> A
A39: 柯奕逢 | B39: 電子碩 / IEE | C39: 314510222 | D39: FALSE | E39: ='Lab01'!K106 -> 88 | F39: ='Lab02'!K106 -> 93.25 | G39: ='Lab03'!U107 -> 91 | H39: ='Lab04'!S107 -> 85 | I39: ='Lab05'!P107 -> 79.25 | J39: ='Final Exam'!W107 -> 64.5 | K39: ='Final Project'!H106 -> 98.4 | L39: =IF(D39=TRUE,0,(E39+F39+G39+H39+I39)*0.12+(J39+K39)*0.2) -> 84.96 | M39: =IF(D39=TRUE,"W",IF(L39>=89.4,"A+",IF(L39>=84.4,"A",IF(L39>=79.4,"A-",IF(L39>=76.4,"B+",IF(L39>=72.4,"B",IF(L39>=69.4,"B-",IF(L39>=66.4,"C+",IF(L39>=62.4,"C",IF(L39>=59.4,"C-",IF(L39>=49.4,"D",IF(L39>0,"E",IF(L39<=0,"X",""))))))))))))) -> A
A40: 彭康軒 | B40: 電機碩 / GEE | C40: 314511040 | D40: FALSE | E40: ='Lab01'!K113 -> 95 | F40: ='Lab02'!K113 -> 93.75 | G40: ='Lab03'!U114 -> 70 | H40: ='Lab04'!S114 -> 83 | I40: ='Lab05'!P114 -> 84.5 | J40: ='Final Exam'!W114 -> 77 | K40: ='Final Project'!H113 -> 91.1 | L40: =IF(D40=TRUE,0,(E40+F40+G40+H40+I40)*0.12+(J40+K40)*0.2) -> 84.77 | M40: =IF(D40=TRUE,"W",IF(L40>=89.4,"A+",IF(L40>=84.4,"A",IF(L40>=79.4,"A-",IF(L40>=76.4,"B+",IF(L40>=72.4,"B",IF(L40>=69.4,"B-",IF(L40>=66.4,"C+",IF(L40>=62.4,"C",IF(L40>=59.4,"C-",IF(L40>=49.4,"D",IF(L40>0,"E",IF(L40<=0,"X",""))))))))))))) -> A
...

Sheet Server Account
A1: 姓名 | B1: 所屬系所 | C1: 學號 | D1: Account
A2: 林知翰 | B2: 土木系 / DCV | C2: 0811254 | D2: dl2025f_001
A3: 林品妤 | B3: 醫工系 / BME | C3: 111261022 | D3: dl2025f_002
A4: 趙立榆 | B4: 電機系 / UEE | C4: 111511003 | D4: dl2025f_003
A5: 劉邦榆 | B5: 電機系 / UEE | C5: 111511005 | D5: dl2025f_004
A6: 林后辰 | B6: 電機系 / UEE | C6: 111511009 | D6: dl2025f_005
A7: 莊之睿 | B7: 電機系 / UEE | C7: 111511010 | D7: dl2025f_006
A8: 郭弋愷 | B8: 電機系 / UEE | C8: 111511057 | D8: dl2025f_007
A9: 茆鎮育 | B9: 電機系 / UEE | C9: 111511059 | D9: dl2025f_008
A10: 簡宗弘 | B10: 電機系 / UEE | C10: 111511093 | D10: dl2025f_009
A11: 林守凡 | B11: 電機系 / UEE | C11: 111511095 | D11: dl2025f_010
A12: 陳禹丞 | B12: 電機系 / UEE | C12: 111511099 | D12: dl2025f_011
A13: 陳郡佑 | B13: 電機系 / UEE | C13: 111511158 | D13: dl2025f_012
A14: 劉哲丞 | B14: 電機系 / UEE | C14: 111511163 | D14: dl2025f_013
... A126: 張子音 | B126: 電子博 / IEE | C126: 413510023 | D126: dl2025f_125
A127: 楊旻頤 | B127: 清華研 | C127: a131051 | D127: dl2025f_126
A128: 劉姿妤 | B128: 清華研 | C128: a141078 | D128: dl2025f_127
A129: 林孟璇 | B129: 清華研 | C129: a141134 | D129: dl2025f_128
A130: 陳侑杰 | B130: 清華研 | C130: v111076 | D130: dl2025f_129

Sheet Lab01
A1: 姓名 | B1: 所屬系所 | C1: 學號 | D1: Task1 | E1: Task2 | F1: Test Acc. | G1: Perf. Rank | H1: Perf Score | I1: Report | J1: Naming Error | K1: Total | L1: Note
A2: 林知翰 | B2: 土木系 / DCV | C2: 0811254 | D2: 40 | E2: 20 | F2: 0.9324 | G2: =RANK(F2,$F$2:$F$130,0) -> 18 | H2: =IF(F2>=0.94,25,IF(F2>=0.928,22,IF(F2>=0.912,19,IF(F2>=0.89,16,IF(F2>=0.868,13,IF(F2>=0.84,10,IF(F2>=0.8,7,IF(F2>0.6,4,"")))))))) -> 22 | I2: 11 | K2: =D2+E2+H2+I2+J2 -> 93
A3: 林品妤 | B3: 醫工系 / BME | C3: 111261022 | D3: 0 | E3: 20 | F3: 0.7081 | G3: =RANK(F3,$F$2:$F$130,0) -> 128 | H3: =IF(F3>=0.94,25,IF(F3>=0.928,22,IF(F3>=0.912,19,IF(F3>=0.89,16,IF(F3>=0.868,13,IF(F3>=0.84,10,IF(F3>=0.8,7,IF(F3>0.6,4,"")))))))) -> 4 | I3: 13 | K3: =D3+E3+H3+I3+J3 -> 37 | L3: Task1正確率未達標
A4: 趙立榆 | B4: 電機系 / UEE | C4: 111511003 | D4: 40 | E4: 20 | F4: 0.9201 | G4: =RANK(F4,$F$2:$F$130,0) -> 43 | H4: =IF(F4>=0.94,25,IF(F4>=0.928,22,IF(F4>=0.912,19,IF(F4>=0.89,16,IF(F4>=0.868,13,IF(F4>=0.84,10,IF(F4>=0.8,7,IF(F4>0.6,4,"")))))))) -> 19 | I4: 12 | K4: =D4+E4+H4+I4+J4 -> 91
A5: 劉邦榆 | B5: 電機系 / UEE | C5: 111511005 | D5: 40 | E5: 20 | F5: 0.9267 | G5: =RANK(F5,$F$2:$F$130,0) -> 28 | H5: =IF(F5>=0.94,25,IF(F5>=0.928,22,IF(F5>=0.912,19,IF(F5>=0.89,16,IF(F5>=0.868,13,IF(F5>=0.84,10,IF(F5>=0.8,7,IF(F5>0.6,4,"")))))))) -> 19 | I5: 14 | K5: =D5+E5+H5+I5+J5 -> 93
A6: 林后辰 | B6: 電機系 / UEE | C6: 111511009 | D6: 40 | E6: 20 | F6: 0.9502 | G6: =RANK(F6,$F$2:$F$130,0) -> 1 | H6: =IF(F6>=0.94,25,IF(F6>=0.928,22,IF(F6>=0.912,19,IF(F6>=0.89,16,IF(F6>=0.868,13,IF(F6>=0.84,10,IF(F6>=0.8,7,IF(F6>0.6,4,"")))))))) -> 25 | I6: 12 | K6: =D6+E6+H6+I6+J6 -> 97
A7: 莊之睿 | B7: 電機系 / UEE | C7: 111511010 | D7: 40 | E7: 20 | F7: 0.9226 | G7: =RANK(F7,$F$2:$F$130,0) -> 40 | H7: =IF(F7>=0.94,25,IF(F7>=0.928,22,IF(F7>=0.912,19,IF(F7>=0.89,16,IF(F7>=0.868,13,IF(F7>=0.84,10,IF(F7>=0.8,7,IF(F7>0.6,4,"")))))))) -> 19 | I7: 12 | K7: =D7+E7+H7+I7+J7 -> 91
A8: 郭弋愷 | B8: 電機系 / UEE | C8: 111511057 | D8: 40 | E8: 20 | F8: 0.8712 | G8: =RANK(F8,$F$2:$F$130,0) -> 109 | H8: =IF(F8>=0.94,25,IF(F8>=0.928,22,IF(F8>=0.912,19,IF(F8>=0.89,16,IF(F8>=0.868,13,IF(F8>=0.84,10,IF(F8>=0.8,7,IF(F8>0.6,4,"")))))))) -> 13 | I8: 12 | K8: =D8+E8+H8+I8+J8 -> 85
A9: 茆鎮育 | B9: 電機系 / UEE | C9: 111511059 | D9: 40 | E9: 20 | F9: 0.8859 | G9: =RANK(F9,$F$2:$F$130,0) -> 94 | H9: =IF(F9>=0.94,25,IF(F9>=0.928,22,IF(F9>=0.912,19,IF(F9>=0.89,16,IF(F9>=0.868,13,IF(F9>=0.84,10,IF(F9>=0.8,7,IF(F9>0.6,4,"")))))))) -> 13 | I9: 11 | K9: =D9+E9+H9+I9+J9 -> 84
A10: 簡宗弘 | B10: 電機系 / UEE | C10: 111511093 | D10: 40 | E10: 20 | F10: 0.9078 | G10: =RANK(F10,$F$2:$F$130,0) -> 59 | H10: =IF(F10>=0.94,25,IF(F10>=0.928,22,IF(F10>=0.912,19,IF(F10>=0.89,16,IF(F10>=0.868,13,IF(F10>=0.84,10,IF(F10>=0.8,7,IF(F10>0.6,4,"")))))))) -> 16 | I10: 10 | K10: =D10+E10+H10+I10+J10 -> 86
A11: 林守凡 | B11: 電機系 / UEE | C11: 111511095 | D11: 40 | E11: 20 | F11: 0.8871 | G11: =RANK(F11,$F$2:$F$130,0) -> 90 | H11: =IF(F11>=0.94,25,IF(F11>=0.928,22,IF(F11>=0.912,19,IF(F11>=0.89,16,IF(F11>=0.868,13,IF(F11>=0.84,10,IF(F11>=0.8,7,IF(F11>0.6,4,"")))))))) -> 13 | I11: 12 | K11: =D11+E11+H11+I11+J11 -> 85
A12: 陳禹丞 | B12: 電機系 / UEE | C12: 111511099 | D12: 40 | E12: 20 | F12: 0.9267 | G12: =RANK(F12,$F$2:$F$130,0) -> 28 | H12: =IF(F12>=0.94,25,IF(F12>=0.928,22,IF(F12>=0.912,19,IF(F12>=0.89,16,IF(F12>=0.868,13,IF(F12>=0.84,10,IF(F12>=0.8,7,IF(F12>0.6,4,"")))))))) -> 19 | I12: 13 | K12: =D12+E12+H12+I12+J12 -> 92
A13: 陳郡佑 | B13: 電機系 / UEE | C13: 111511158 | D13: 40 | E13: 20 | F13: 0.8924 | G13: =RANK(F13,$F$2:$F$130,0) -> 83 | H13: =IF(F13>=0.94,25,IF(F13>=0.928,22,IF(F13>=0.912,19,IF(F13>=0.89,16,IF(F13>=0.868,13,IF(F13>=0.84,10,IF(F13>=0.8,7,IF(F13>0.6,4,"")))))))) -> 16 | I13: 10 | K13: =D13+E13+H13+I13+J13 -> 86
A14: 劉哲丞 | B14: 電機系 / UEE | C14: 111511163 | D14: 40 | E14: 20 | F14: 0.8534 | G14: =RANK(F14,$F$2:$F$130,0) -> 119 | H14: =IF(F14>=0.94,25,IF(F14>=0.928,22,IF(F14>=0.912,19,IF(F14>=0.89,16,IF(F14>=0.868,13,IF(F14>=0.84,10,IF(F14>=0.8,7,IF(F14>0.6,4,"")))))))) -> 10 | I14: 11 | K14: =D14+E14+H14+I14+J14 -> 81
A15: 鍾宗揚 | B15: 電機系 / UEE | C15: 111511186 | D15: 40 | E15: 20 | F15: 0.9035 | G15: =RANK(F15,$F$2:$F$130,0) -> 67 | H15: =IF(F15>=0.94,25,IF(F15>=0.928,22,IF(F15>=0.912,19,IF(F15>=0.89,16,IF(F15>=0.868,13,IF(F15>=0.84,10,IF(F15>=0.8,7,IF(F15>0.6,4,"")))))))) -> 16 | I15: 14 | K15: =D15+E15+H15+I15+J15 -> 90
... A25: 黃治鈞 | B25: 電機系 / UEE | C25: 111511306 | D25: 40 | E25: 20 | F25: 0.9435 | G25: =RANK(F25,$F$2:$F$130,0) -> 4 | H25: =IF(F25>=0.94,25,IF(F25>=0.928,22,IF(F25>=0.912,19,IF(F25>=0.89,16,IF(F25>=0.868,13,IF(F25>=0.84,10,IF(F25>=0.8,7,IF(F25>0.6,4,"")))))))) -> 25 | I25: 11 | K25: =D25+E25+H25+I25+J25 -> 96
A26: 唐以理 | B26: 電機系 / UEE | C26: 111511307 | D26: 35 | E26: 15 | F26: 0.9256 | G26: =RANK(F26,$F$2:$F$130,0) -> 32 | H26: =IF(F26>=0.94,25,IF(F26>=0.928,22,IF(F26>=0.912,19,IF(F26>=0.89,16,IF(F26>=0.868,13,IF(F26>=0.84,10,IF(F26>=0.8,7,IF(F26>0.6,4,"")))))))) -> 19 | I26: 8 | K26: =D26+E26+H26+I26+J26 -> 77 | L26: 未附上截圖
A27: 陳奕廷 | B27: 電機系 / UEE | C27: 111511308 | D27: 40 | E27: 20 | F27: 0.929 | G27: =RANK(F27,$F$2:$F$130,0) -> 25 | H27: =IF(F27>=0.94,25,IF(F27>=0.928,22,IF(F27>=0.912,19,IF(F27>=0.89,16,IF(F27>=0.868,13,IF(F27>=0.84,10,IF(F27>=0.8,7,IF(F27>0.6,4,"")))))))) -> 22 | I27: 13 | K27: =D27+E27+H27+I27+J27 -> 95
A28: 薛天其 | B28: 電機系 / UEE | C28: 111610032 | D28: 40 | E28: 20 | F28: 0.9142 | G28: =RANK(F28,$F$2:$F$130,0) -> 53 | H28: =IF(F28>=0.94,25,IF(F28>=0.928,22,IF(F28>=0.912,19,IF(F28>=0.89,16,IF(F28>=0.868,13,IF(F28>=0.84,10,IF(F28>=0.8,7,IF(F28>0.6,4,"")))))))) -> 19 | I28: 13 | K28: =D28+E28+H28+I28+J28 -> 92
A29: 林柏伸 | B29: 電機系 / UEE | C29: 111611088 | D29: 40 | E29: 20 | F29: 0.9267 | G29: =RANK(F29,$F$2:$F$130,0) -> 28 | H29: =IF(F29>=0.94,25,IF(F29>=0.928,22,IF(F29>=0.912,19,IF(F29>=0.89,16,IF(F29>=0.868,13,IF(F29>=0.84,10,IF(F29>=0.8,7,IF(F29>0.6,4,"")))))))) -> 19 | I29: 11 | K29: =D29+E29+H29+I29+J29 -> 90
A30: 謝歷恩 | B30: 電機系 / UEE | C30: 111651009 | D30: 40 | E30: 20 | F30: 0.9022 | G30: =RANK(F30,$F$2:$F$130,0) -> 70 | H30: =IF(F30>=0.94,25,IF(F30>=0.928,22,IF(F30>=0.912,19,IF(F30>=0.89,16,IF(F30>=0.868,13,IF(F30>=0.84,10,IF(F30>=0.8,7,IF(F30>0.6,4,"")))))))) -> 16 | I30: 11 | K30: =D30+E30+H30+I30+J30 -> 87
A31: 鐘邦郡 | B31: 資工系 / DCP | C31: 111652031 | D31: 40 | E31: 20 | F31: 0.9051 | G31: =RANK(F31,$F$2:$F$130,0) -> 66 | H31: =IF(F31>=0.94,25,IF(F31>=0.928,22,IF(F31>=0.912,19,IF(F31>=0.89,16,IF(F31>=0.868,13,IF(F31>=0.84,10,IF(F31>=0.8,7,IF(F31>0.6,4,"")))))))) -> 16 | I31: 12 | K31: =D31+E31+H31+I31+J31 -> 88
A32: 吳俊叡 | B32: 電機系 / UEE | C32: 112511152 | D32: 40 | E32: 20 | F32: 0.878 | G32: =RANK(F32,$F$2:$F$130,0) -> 106 | H32: =IF(F32>=0.94,25,IF(F32>=0.928,22,IF(F32>=0.912,19,IF(F32>=0.89,16,IF(F32>=0.868,13,IF(F32>=0.84,10,IF(F32>=0.8,7,IF(F32>0.6,4,"")))))))) -> 13 | I32: 7 | K32: =D32+E32+H32+I32+J32 -> 80
A33: 黃子倫 | B33: 電子碩 / IEE | C33: 311510190 | D33: 40 | E33: 20 | F33: 0.8183 | G33: =RANK(F33,$F$2:$F$130,0) -> 126 | H33: =IF(F33>=0.94,25,IF(F33>=0.928,22,IF(F33>=0.912,19,IF(F33>=0.89,16,IF(F33>=0.868,13,IF(F33>=0.84,10,IF(F33>=0.8,7,IF(F33>0.6,4,"")))))))) -> 7 | I33: 10 | K33: =D33+E33+H33+I33+J33 -> 77
A34: 林益葳 | B34: 電子博 / IEE | C34: 311515050 | D34: 40 | E34: 20 | F34: 0.881 | G34: =RANK(F34,$F$2:$F$130,0) -> 104 | H34: =IF(F34>=0.94,25,IF(F34>=0.928,22,IF(F34>=0.912,19,IF(F34>=0.89,16,IF(F34>=0.868,13,IF(F34>=0.84,10,IF(F34>=0.8,7,IF(F34>0.6,4,"")))))))) -> 13 | I34: 12 | K34: =D34+E34+H34+I34+J34 -> 85
A35: 張譽耀 | B35: 電子碩 / IEE | C35: 312510067 | D35: 40 | E35: 20 | F35: 0.86 | G35: =RANK(F35,$F$2:$F$130,0) -> 116 | H35: =IF(F35>=0.94,25,IF(F35>=0.928,22,IF(F35>=0.912,19,IF(F35>=0.89,16,IF(F35>=0.868,13,IF(F35>=0.84,10,IF(F35>=0.8,7,IF(F35>0.6,4,"")))))))) -> 10 | I35: 8 | K35: =D35+E35+H35+I35+J35 -> 78
A36: 邱棋胤 | B36: 電子碩 / IEE | C36: 312510123 | D36: 40 | E36: 20 | F36: 0.8649 | G36: =RANK(F36,$F$2:$F$130,0) -> 113 | H36: =IF(F36>=0.94,25,IF(F36>=0.928,22,IF(F36>=0.912,19,IF(F36>=0.89,16,IF(F36>=0.868,13,IF(F36>=0.84,10,IF(F36>=0.8,7,IF(F36>0.6,4,"")))))))) -> 10 | I36: 10 | K36: =D36+E36+H36+I36+J36 -> 80
A37: 黃建廷 | B37: 電機碩 / GEE | C37: 312511041 | D37: 40 | E37: 20 | F37: 0.9028 | G37: =RANK(F37,$F$2:$F$130,0) -> 68 | H37: =IF(F37>=0.94,25,IF(F37>=0.928,22,IF(F37>=0.912,19,IF(F37>=0.89,16,IF(F37>=0.868,13,IF(F37>=0.84,10,IF(F37>=0.8,7,IF(F37>0.6,4,"")))))))) -> 16 | I37: 11 | K37: =D37+E37+H37+I37+J37 -> 87
A38: 余唯愷 | B38: 電子博 / IEE | C38: 312580021 | D38: 40 | E38: 20 | F38: 0.9294 | G38: =RANK(F38,$F$2:$F$130,0) -> 24 | H38: =IF(F38>=0.94,25,IF(F38>=0.928,22,IF(F38>=0.912,19,IF(F38>=0.89,16,IF(F38>=0.868,13,IF(F38>=0.84,10,IF(F38>=0.8,7,IF(F38>0.6,4,"")))))))) -> 22 | I38: 10 | K38: =D38+E38+H38+I38+J38 -> 92
... A48: 林槿茹 | B48: 電子碩 / IEE | C48: 313510178 | D48: 40 | E48: 20 | F48: 0.8813 | G48: =RANK(F48,$F$2:$F$130,0) -> 103 | H48: =IF(F48>=0.94,25,IF(F48>=0.928,22,IF(F48>=0.912,19,IF(F48>=0.89,16,IF(F48>=0.868,13,IF(F48>=0.84,10,IF(F48>=0.8,7,IF(F48>0.6,4,"")))))))) -> 13 | I48: 13 | K48: =D48+E48+H48+I48+J48 -> 86
A49: 宋玉磊 | B49: 電子碩 / IEE | C49: 313510194 | D49: 35 | E49: 15 | F49: 0.8503 | G49: =RANK(F49,$F$2:$F$130,0) -> 122 | H49: =IF(F49>=0.94,25,IF(F49>=0.928,22,IF(F49>=0.912,19,IF(F49>=0.89,16,IF(F49>=0.868,13,IF(F49>=0.84,10,IF(F49>=0.8,7,IF(F49>0.6,4,"")))))))) -> 10 | I49: 11 | K49: =D49+E49+H49+I49+J49 -> 71 | L49: 未附上截圖
A50: 吳彥忞 | B50: 電子碩 / IEE | C50: 313510196 | D50: 40 | E50: 20 | F50: 0.8857 | G50: =RANK(F50,$F$2:$F$130,0) -> 95 | H50: =IF(F50>=0.94,25,IF(F50>=0.928,22,IF(F50>=0.912,19,IF(F50>=0.89,16,IF(F50>=0.868,13,IF(F50>=0.84,10,IF(F50>=0.8,7,IF(F50>0.6,4,"")))))))) -> 13 | I50: 12 | K50: =D50+E50+H50+I50+J50 -> 85
A51: 廖紹閔 | B51: 電子碩 / IEE | C51: 313510212 | D51: 0 | E51: 0 | H51: 0 | I51: 0 | K51: =D51+E51+H51+I51+J51 -> 0
A52: 王睿哲 | B52: 電子碩 / IEE | C52: 313510214 | D52: 40 | E52: 20 | F52: 0.9165 | G52: =RANK(F52,$F$2:$F$130,0) -> 49 | H52: =IF(F52>=0.94,25,IF(F52>=0.928,22,IF(F52>=0.912,19,IF(F52>=0.89,16,IF(F52>=0.868,13,IF(F52>=0.84,10,IF(F52>=0.8,7,IF(F52>0.6,4,"")))))))) -> 19 | I52: 12 | K52: =D52+E52+H52+I52+J52 -> 91
A53: 康鈞睿 | B53: 電子碩 / IEE | C53: 313510217 | D53: 40 | E53: 20 | F53: 0.9229 | G53: =RANK(F53,$F$2:$F$130,0) -> 39 | H53: =IF(F53>=0.94,25,IF(F53>=0.928,22,IF(F53>=0.912,19,IF(F53>=0.89,16,IF(F53>=0.868,13,IF(F53>=0.84,10,IF(F53>=0.8,7,IF(F53>0.6,4,"")))))))) -> 19 | I53: 9 | K53: =D53+E53+H53+I53+J53 -> 88
A54: 李崇碩 | B54: 電子碩 / IEE | C54: 313510230 | D54: 40 | E54: 20 | F54: 0.9398 | G54: =RANK(F54,$F$2:$F$130,0) -> 9 | H54: =IF(F54>=0.94,25,IF(F54>=0.928,22,IF(F54>=0.912,19,IF(F54>=0.89,16,IF(F54>=0.868,13,IF(F54>=0.84,10,IF(F54>=0.8,7,IF(F54>0.6,4,"")))))))) -> 22 | I54: 14 | K54: =D54+E54+H54+I54+J54 -> 96
A55: 張皓庭 | B55: 電子碩 / IEE | C55: 313510234 | D55: 40 | E55: 20 | F55: 0.8804 | G55: =RANK(F55,$F$2:$F$130,0) -> 105 | H55: =IF(F55>=0.94,25,IF(F55>=0.928,22,IF(F55>=0.912,19,IF(F55>=0.89,16,IF(F55>=0.868,13,IF(F55>=0.84,10,IF(F55>=0.8,7,IF(F55>0.6,4,"")))))))) -> 13 | I55: 10 | K55: =D55+E55+H55+I55+J55 -> 83
A56: 陳冠辰 | B56: 電子碩 / IEE | C56: 313510237 | D56: 40 | E56: 20 | F56: 0.9323 | G56: =RANK(F56,$F$2:$F$130,0) -> 19 | H56: =IF(F56>=0.94,25,IF(F56>=0.928,22,IF(F56>=0.912,19,IF(F56>=0.89,16,IF(F56>=0.868,13,IF(F56>=0.84,10,IF(F56>=0.8,7,IF(F56>0.6,4,"")))))))) -> 22 | I56: 12 | K56: =D56+E56+H56+I56+J56 -> 94
A57: 阮楷勳 | B57: 電子碩 / IEE | C57: 313510244 | D57: 40 | E57: 20 | F57: 0.9331 | G57: =RANK(F57,$F$2:$F$130,0) -> 15 | H57: =IF(F57>=0.94,25,IF(F57>=0.928,22,IF(F57>=0.912,19,IF(F57>=0.89,16,IF(F57>=0.868,13,IF(F57>=0.84,10,IF(F57>=0.8,7,IF(F57>0.6,4,"")))))))) -> 22 | I57: 12 | K57: =D57+E57+H57+I57+J57 -> 94
A58: 鄭人傑 | B58: 電子碩 / IEE | C58: 313510245 | D58: 40 | E58: 20 | F58: 0.9312 | G58: =RANK(F58,$F$2:$F$130,0) -> 20 | H58: =IF(F58>=0.94,25,IF(F58>=0.928,22,IF(F58>=0.912,19,IF(F58>=0.89,16,IF(F58>=0.868,13,IF(F58>=0.84,10,IF(F58>=0.8,7,IF(F58>0.6,4,"")))))))) -> 22 | I58: 12 | K58: =D58+E58+H58+I58+J58 -> 94
...

Sheet Lab02
A1: =30*0.7 -> 21 | B1: 所屬系所 | C1: 學號 | D1: Architecture Check | E1: Task1 (30%) | F1: Task2 (30%) | G1: Report (30%) | H1: Test MAE | I1: Perf. Score (10%) | J1: Naming Error | K1: Total | L1: Note
A2: 林知翰 | B2: 土木系 / DCV | C2: 0811254 | D2: ✓ | E2: =IF(ISBLANK($D2),0,30-VLOOKUP($D2, $D$133:$E$149, 2, FALSE)) -> 30 | F2: 30 | G2: 22 | I2: =IF(ISBLANK($H2),0,INDEX({10,8.75,7.5,6.25,5,3.75,2.5,1.25},IFERROR(MATCH($H2,$H$135:$H$141,1),0)+1)) -> 0 | K2: =E2+F2+I2+G2+J2 -> 82 | L2: Checkpoint parsing error
A3: 林品妤 | B3: 醫工系 / BME | C3: 111261022 | D3: recursive layer | E3: =IF(ISBLANK($D3),0,30-VLOOKUP($D3, $D$133:$E$149, 2, FALSE)) -> 25 | F3: 0 | G3: 28 | H3: 4.4225 | I3: =IF(ISBLANK($H3),0,INDEX({10,8.75,7.5,6.25,5,3.75,2.5,1.25},IFERROR(MATCH($H3,$H$135:$H$141,1),0)+1)) -> 1.25 | K3: =E3+F3+I3+G3+J3 -> 54.25
A4: 趙立榆 | B4: 電機系 / UEE | C4: 111511003 | E4: =IF(ISBLANK($D4),0,30-VLOOKUP($D4, $D$133:$E$149, 2, FALSE)) -> 0 | I4: =IF(ISBLANK($H4),0,INDEX({10,8.75,7.5,6.25,5,3.75,2.5,1.25},IFERROR(MATCH($H4,$H$135:$H$141,1),0)+1)) -> 0 | K4: =E4+F4+I4+G4+J4 -> 0 | L4: No submission
A5: 劉邦榆 | B5: 電機系 / UEE | C5: 111511005 | E5: =IF(ISBLANK($D5),0,30-VLOOKUP($D5, $D$133:$E$149, 2, FALSE)) -> 0 | I5: =IF(ISBLANK($H5),0,INDEX({10,8.75,7.5,6.25,5,3.75,2.5,1.25},IFERROR(MATCH($H5,$H$135:$H$141,1),0)+1)) -> 0 | K5: =E5+F5+I5+G5+J5 -> 0 | L5: No submission
A6: 林后辰 | B6: 電機系 / UEE | C6: 111511009 | D6: ✓ | E6: =IF(ISBLANK($D6),0,30-VLOOKUP($D6, $D$133:$E$149, 2, FALSE)) -> 30 | F6: 30 | G6: 27 | H6: 2.4175 | I6: =IF(ISBLANK($H6),0,INDEX({10,8.75,7.5,6.25,5,3.75,2.5,1.25},IFERROR(MATCH($H6,$H$135:$H$141,1),0)+1)) -> 10 | K6: =E6+F6+I6+G6+J6 -> 97
A7: 莊之睿 | B7: 電機系 / UEE | C7: 111511010 | D7: ✓ | E7: =IF(ISBLANK($D7),0,30-VLOOKUP($D7, $D$133:$E$149, 2, FALSE)) -> 30 | F7: 30 | G7: 26 | H7: 3.0392 | I7: =IF(ISBLANK($H7),0,INDEX({10,8.75,7.5,6.25,5,3.75,2.5,1.25},IFERROR(MATCH($H7,$H$135:$H$141,1),0)+1)) -> 6.25 | K7: =E7+F7+I7+G7+J7 -> 92.25
A8: 郭弋愷 | B8: 電機系 / UEE | C8: 111511057 | D8: LDB #channel mismatch | E8: =IF(ISBLANK($D8),0,30-VLOOKUP($D8, $D$133:$E$149, 2, FALSE)) -> 20 | F8: 30 | G8: 28 | H8: 2.7422 | I8: =IF(ISBLANK($H8),0,INDEX({10,8.75,7.5,6.25,5,3.75,2.5,1.25},IFERROR(MATCH($H8,$H$135:$H$141,1),0)+1)) -> 8.75 | K8: =E8+F8+I8+G8+J8 -> 86.75
A9: 茆鎮育 | B9: 電機系 / UEE | C9: 111511059 | E9: =IF(ISBLANK($D9),0,30-VLOOKUP($D9, $D$133:$E$149, 2, FALSE)) -> 0 | I9: =IF(ISBLANK($H9),0,INDEX({10,8.75,7.5,6.25,5,3.75,2.5,1.25},IFERROR(MATCH($H9,$H$135:$H$141,1),0)+1)) -> 0 | K9: =E9+F9+I9+G9+J9 -> 0 | L9: No submission
A10: 簡宗弘 | B10: 電機系 / UEE | C10: 111511093 | D10: ✓ | E10: =IF(ISBLANK($D10),0,30-VLOOKUP($D10, $D$133:$E$149, 2, FALSE)) -> 30 | F10: 30 | G10: 23 | H10: 2.9736 | I10: =IF(ISBLANK($H10),0,INDEX({10,8.75,7.5,6.25,5,3.75,2.5,1.25},IFERROR(MATCH($H10,$H$135:$H$141,1),0)+1)) -> 6.25 | K10: =E10+F10+I10+G10+J10 -> 89.25
A11: 林守凡 | B11: 電機系 / UEE | C11: 111511095 | D11: ✓ | E11: =IF(ISBLANK($D11),0,30-VLOOKUP($D11, $D$133:$E$149, 2, FALSE)) -> 30 | F11: 30 | G11: 23 | H11: 3.1307 | I11: =IF(ISBLANK($H11),0,INDEX({10,8.75,7.5,6.25,5,3.75,2.5,1.25},IFERROR(MATCH($H11,$H$135:$H$141,1),0)+1)) -> 5 | K11: =E11+F11+I11+G11+J11 -> 88
A12: 陳禹丞 | B12: 電機系 / UEE | C12: 111511099 | D12: connectivity error | E12: =IF(ISBLANK($D12),0,30-VLOOKUP($D12, $D$133:$E$149, 2, FALSE)) -> 22.5 | F12: 0 | G12: 24 | H12: 2.5855 | I12: =IF(ISBLANK($H12),0,INDEX({10,8.75,7.5,6.25,5,3.75,2.5,1.25},IFERROR(MATCH($H12,$H$135:$H$141,1),0)+1)) -> 8.75 | K12: =E12+F12+I12+G12+J12 -> 55.25
A13: 陳郡佑 | B13: 電機系 / UEE | C13: 111511158 | D13: ✓ | E13: =IF(ISBLANK($D13),0,30-VLOOKUP($D13, $D$133:$E$149, 2, FALSE)) -> 30 | F13: 30 | G13: 24 | H13: 3.9134 | I13: =IF(ISBLANK($H13),0,INDEX({10,8.75,7.5,6.25,5,3.75,2.5,1.25},IFERROR(MATCH($H13,$H$135:$H$141,1),0)+1)) -> 2.5 | K13: =E13+F13+I13+G13+J13 -> 86.5
A14: 劉哲丞 | B14: 電機系 / UEE | C14: 111511163 | D14: LDB #layer mismatch | E14: =IF(ISBLANK($D14),0,30-VLOOKUP($D14, $D$133:$E$149, 2, FALSE)) -> 15 | F14: 30 | G14: 18 | H14: 13.2835 | I14: =IF(ISBLANK($H14),0,INDEX({10,8.75,7.5,6.25,5,3.75,2.5,1.25},IFERROR(MATCH($H14,$H$135:$H$141,1),0)+1)) -> 1.25 | K14: =E14+F14+I14+G14+J14 -> 64.25
A15: 鍾宗揚 | B15: 電機系 / UEE | C15: 111511186 | D15: ✓ | E15: =IF(ISBLANK($D15),0,30-VLOOKUP($D15, $D$133:$E$149, 2, FALSE)) -> 30 | F15: 30 | G15: 20 | H15: 3.1679 | I15: =IF(ISBLANK($H15),0,INDEX({10,8.75,7.5,6.25,5,3.75,2.5,1.25},IFERROR(MATCH($H15,$H$135:$H$141,1),0)+1)) -> 5 | K15: =E15+F15+I15+G15+J15 -> 85
A16: 林文遠 | B16: 電機系 / UEE | C16: 111511208 | D16: connectivity error | E16: =IF(ISBLANK($D16),0,30-VLOOKUP($D16, $D$133:$E$149, 2, FALSE)) -> 22.5 | F16: 30 | G16: 21 | H16: 3.1631 | I16: =IF(ISBLANK($H16),0,INDEX({10,8.75,7.5,6.25,5,3.75,2.5,1.25},IFERROR(MATCH($H16,$H$135:$H$141,1),0)+1)) -> 5 | K16: =E16+F16+I16+G16+J16 -> 78.5
A17: 賴柏任 | B17: 電機系 / UEE | C17: 111511211 | D17: ✓ | E17: =IF(ISBLANK($D17),0,30-VLOOKUP($D17, $D$133:$E$149, 2, FALSE)) -> 30 | F17: 30 | G17: 24 | H17: 2.8188 | I17: =IF(ISBLANK($H17),0,INDEX({10,8.75,7.5,6.25,5,3.75,2.5,1.25},IFERROR(MATCH($H17,$H$135:$H$141,1),0)+1)) -> 7.5 | K17: =E17+F17+I17+G17+J17 -> 91.5
A18: 王乙棠 | B18: 電機系 / UEE | C18: 111511240 | D18: LDB 1x1Conv missing | E18: =IF(ISBLANK($D18),0,30-VLOOKUP($D18, $D$133:$E$149, 2, FALSE)) -> 20 | F18: 30 | G18: 27 | H18: 2.6645 | I18: =IF(ISBLANK($H18),0,INDEX({10,8.75,7.5,6.25,5,3.75,2.5,1.25},IFERROR(MATCH($H18,$H$135:$H$141,1),0)+1)) -> 8.75 | K18: =E18+F18+I18+G18+J18 -> 85.75
A19: 李宇翔 | B19: 電機系 / UEE | C19: 111511247 | D19: ✓ | E19: =IF(ISBLANK($D19),0,30-VLOOKUP($D19, $D$133:$E$149, 2, FALSE)) -> 30 | F19: 30 | G19: 26 | H19: 3.2929 | I19: =IF(ISBLANK($H19),0,INDEX({10,8.75,7.5,6.25,5,3.75,2.5,1.25},IFERROR(MATCH($H19,$H$135:$H$141,1),0)+1)) -> 3.75 | K19: =E19+F19+I19+G19+J19 -> 89.75
A20: 李昱承 | B20: 電機系 / UEE | C20: 111511249 | D20: Transition wrong layer order | E20: =IF(ISBLANK($D20),0,30-VLOOKUP($D20, $D$133:$E$149, 2, FALSE)) -> 20 | F20: 30 | G20: 22 | H20: 2.7938 | I20: =IF(ISBLANK($H20),0,INDEX({10,8.75,7.5,6.25,5,3.75,2.5,1.25},IFERROR(MATCH($H20,$H$135:$H$141,1),0)+1)) -> 7.5 | K20: =E20+F20+I20+G20+J20 -> 79.5
A21: 鄭丞佑 | B21: 電機系 / UEE | C21: 111511253 | D21: ✓ | E21: =IF(ISBLANK($D21),0,30-VLOOKUP($D21, $D$133:$E$149, 2, FALSE)) -> 30 | F21: 30 | G21: 19 | H21: 3.741 | I21: =IF(ISBLANK($H21),0,INDEX({10,8.75,7.5,6.25,5,3.75,2.5,1.25},IFERROR(MATCH($H21,$H$135:$H$141,1),0)+1)) -> 2.5 | K21: =E21+F21+I21+G21+J21 -> 81.5
... A23: 洪偉軒 | B23: 電機系 / UEE | C23: 111511263 | D23: ✓ | E23: =IF(ISBLANK($D23),0,30-VLOOKUP($D23, $D$133:$E$149, 2, FALSE)) -> 30 | F23: 30 | G23: 22 | H23: 3.9489 | I23: =IF(ISBLANK($H23),0,INDEX({10,8.75,7.5,6.25,5,3.75,2.5,1.25},IFERROR(MATCH($H23,$H$135:$H$141,1),0)+1)) -> 1.25 | K23: =E23+F23+I23+G23+J23 -> 83.25
A24: 陳沿霖 | B24: 電機系 / UEE | C24: 111511273 | E24: =IF(ISBLANK($D24),0,30-VLOOKUP($D24, $D$133:$E$149, 2, FALSE)) -> 0 | F24: 30 | G24: 22 | I24: =IF(ISBLANK($H24),0,INDEX({10,8.75,7.5,6.25,5,3.75,2.5,1.25},IFERROR(MATCH($H24,$H$135:$H$141,1),0)+1)) -> 0 | K24: =E24+F24+I24+G24+J24 -> 52 | L24: Empty python file
A25: 黃治鈞 | B25: 電機系 / UEE | C25: 111511306 | D25: ✓ | E25: =IF(ISBLANK($D25),0,30-VLOOKUP($D25, $D$133:$E$149, 2, FALSE)) -> 30 | F25: 30 | G25: 23 | H25: 3.102 | I25: =IF(ISBLANK($H25),0,INDEX({10,8.75,7.5,6.25,5,3.75,2.5,1.25},IFERROR(MATCH($H25,$H$135:$H$141,1),0)+1)) -> 5 | K25: =E25+F25+I25+G25+J25 -> 88
A26: 唐以理 | B26: 電機系 / UEE | C26: 111511307 | D26: ✓ | E26: =IF(ISBLANK($D26),0,30-VLOOKUP($D26, $D$133:$E$149, 2, FALSE)) -> 30 | F26: 30 | G26: 25 | H26: 3.0752 | I26: =IF(ISBLANK($H26),0,INDEX({10,8.75,7.5,6.25,5,3.75,2.5,1.25},IFERROR(MATCH($H26,$H$135:$H$141,1),0)+1)) -> 5 | K26: =E26+F26+I26+G26+J26 -> 90
A27: 陳奕廷 | B27: 電機系 / UEE | C27: 111511308 | D27: Stem layer error | E27: =IF(ISBLANK($D27),0,30-VLOOKUP($D27, $D$133:$E$149, 2, FALSE)) -> 15 | F27: 30 | G27: 23 | H27: 3.2133 | I27: =IF(ISBLANK($H27),0,INDEX({10,8.75,7.5,6.25,5,3.75,2.5,1.25},IFERROR(MATCH($H27,$H$135:$H$141,1),0)+1)) -> 3.75 | K27: =E27+F27+I27+G27+J27 -> 71.75
A28: 薛天其 | B28: 電機系 / UEE | C28: 111610032 | D28: ✓ | E28: =IF(ISBLANK($D28),0,30-VLOOKUP($D28, $D$133:$E$149, 2, FALSE)) -> 30 | F28: 30 | G28: 26 | H28: 2.8388 | I28: =IF(ISBLANK($H28),0,INDEX({10,8.75,7.5,6.25,5,3.75,2.5,1.25},IFERROR(MATCH($H28,$H$135:$H$141,1),0)+1)) -> 7.5 | J28: -5 | K28: =E28+F28+I28+G28+J28 -> 88.5 | L28: Incomplete file name (no extension)
A29: 林柏伸 | B29: 電機系 / UEE | C29: 111611088 | D29: ✓ | E29: =IF(ISBLANK($D29),0,30-VLOOKUP($D29, $D$133:$E$149, 2, FALSE)) -> 30 | F29: 30 | G29: 25 | H29: 2.6097 | I29: =IF(ISBLANK($H29),0,INDEX({10,8.75,7.5,6.25,5,3.75,2.5,1.25},IFERROR(MATCH($H29,$H$135:$H$141,1),0)+1)) -> 8.75 | K29: =E29+F29+I29+G29+J29 -> 93.75
A30: 謝歷恩 | B30: 電機系 / UEE | C30: 111651009 | D30: LDB reduce 3x3Conv missing | E30: =IF(ISBLANK($D30),0,30-VLOOKUP($D30, $D$133:$E$149, 2, FALSE)) -> 20 | F30: 30 | G30: 27 | H30: 2.9458 | I30: =IF(ISBLANK($H30),0,INDEX({10,8.75,7.5,6.25,5,3.75,2.5,1.25},IFERROR(MATCH($H30,$H$135:$H$141,1),0)+1)) -> 6.25 | K30: =E30+F30+I30+G30+J30 -> 83.25
A31: 鐘邦郡 | B31: 資工系 / DCP | C31: 111652031 | D31: ✓ | E31: =IF(ISBLANK($D31),0,30-VLOOKUP($D31, $D$133:$E$149, 2, FALSE)) -> 30 | F31: 30 | G31: 25 | H31: 2.8478 | I31: =IF(ISBLANK($H31),0,INDEX({10,8.75,7.5,6.25,5,3.75,2.5,1.25},IFERROR(MATCH($H31,$H$135:$H$141,1),0)+1)) -> 7.5 | K31: =E31+F31+I31+G31+J31 -> 92.5
A32: 吳俊叡 | B32: 電機系 / UEE | C32: 112511152 | D32: ✓ | E32: =IF(ISBLANK($D32),0,30-VLOOKUP($D32, $D$133:$E$149, 2, FALSE)) -> 30 | F32: 30 | G32: 23 | I32: =IF(ISBLANK($H32),0,INDEX({10,8.75,7.5,6.25,5,3.75,2.5,1.25},IFERROR(MATCH($H32,$H$135:$H$141,1),0)+1)) -> 0 | K32: =E32+F32+I32+G32+J32 -> 83 | L32: Checkpoint parsing error
A33: 黃子倫 | B33: 電子碩 / IEE | C33: 311510190 | D33: LDB #layer mismatch | E33: =IF(ISBLANK($D33),0,30-VLOOKUP($D33, $D$133:$E$149, 2, FALSE)) -> 15 | F33: 0 | G33: 23 | H33: 2.9431 | I33: =IF(ISBLANK($H33),0,INDEX({10,8.75,7.5,6.25,5,3.75,2.5,1.25},IFERROR(MATCH($H33,$H$135:$H$141,1),0)+1)) -> 6.25 | K33: =E33+F33+I33+G33+J33 -> 44.25 | L33: No Task2 screenshot
A34: 林益葳 | B34: 電子博 / IEE | C34: 311515050 | D34: LDB #layer mismatch | E34: =IF(ISBLANK($D34),0,30-VLOOKUP($D34, $D$133:$E$149, 2, FALSE)) -> 15 | F34: 30 | G34: 22 | H34: 3.5576 | I34: =IF(ISBLANK($H34),0,INDEX({10,8.75,7.5,6.25,5,3.75,2.5,1.25},IFERROR(MATCH($H34,$H$135:$H$141,1),0)+1)) -> 2.5 | K34: =E34+F34+I34+G34+J34 -> 69.5
A35: 張譽耀 | B35: 電子碩 / IEE | C35: 312510067 | D35: connectivity error | E35: =IF(ISBLANK($D35),0,30-VLOOKUP($D35, $D$133:$E$149, 2, FALSE)) -> 22.5 | F35: 30 | G35: 23 | H35: 2.8125 | I35: =IF(ISBLANK($H35),0,INDEX({10,8.75,7.5,6.25,5,3.75,2.5,1.25},IFERROR(MATCH($H35,$H$135:$H$141,1),0)+1)) -> 7.5 | K35: =E35+F35+I35+G35+J35 -> 83
A36: 邱棋胤 | B36: 電子碩 / IEE | C36: 312510123 | D36: ✓ | E36: =IF(ISBLANK($D36),0,30-VLOOKUP($D36, $D$133:$E$149, 2, FALSE)) -> 30 | F36: 30 | G36: 22 | H36: 2.1993 | I36: =IF(ISBLANK($H36),0,INDEX({10,8.75,7.5,6.25,5,3.75,2.5,1.25},IFERROR(MATCH($H36,$H$135:$H$141,1),0)+1)) -> 10 | K36: =E36+F36+I36+G36+J36 -> 92
A37: 黃建廷 | B37: 電機碩 / GEE | C37: 312511041 | D37: ✓ | E37: =IF(ISBLANK($D37),0,30-VLOOKUP($D37, $D$133:$E$149, 2, FALSE)) -> 30 | F37: 30 | G37: 22 | H37: 2.9846 | I37: =IF(ISBLANK($H37),0,INDEX({10,8.75,7.5,6.25,5,3.75,2.5,1.25},IFERROR(MATCH($H37,$H$135:$H$141,1),0)+1)) -> 6.25 | K37: =E37+F37+I37+G37+J37 -> 88.25
A38: 余唯愷 | B38: 電子博 / IEE | C38: 312580021 | D38: ✓ | E38: =IF(ISBLANK($D38),0,30-VLOOKUP($D38, $D$133:$E$149, 2, FALSE)) -> 30 | F38: 30 | G38: 26 | H38: 2.8518 | I38: =IF(ISBLANK($H38),0,INDEX({10,8.75,7.5,6.25,5,3.75,2.5,1.25},IFERROR(MATCH($H38,$H$135:$H$141,1),0)+1)) -> 7.5 | K38: =E38+F38+I38+G38+J38 -> 93.5
A39: 胡芮墉 | B39: 電機碩 / GEE | C39: 312580041 | D39: connectivity error | E39: =IF(ISBLANK($D39),0,30-VLOOKUP($D39, $D$133:$E$149, 2, FALSE)) -> 22.5 | F39: 30 | G39: 21 | H39: 2.9029 | I39: =IF(ISBLANK($H39),0,INDEX({10,8.75,7.5,6.25,5,3.75,2.5,1.25},IFERROR(MATCH($H39,$H$135:$H$141,1),0)+1)) -> 7.5 | K39: =E39+F39+I39+G39+J39 -> 81
A40: 陳沛鴻 | B40: 前瞻半導體 / Pio-SEMI | C40: 312580072 | E40: =IF(ISBLANK($D40),0,30-VLOOKUP($D40, $D$133:$E$149, 2, FALSE)) -> 0 | I40: =IF(ISBLANK($H40),0,INDEX({10,8.75,7.5,6.25,5,3.75,2.5,1.25},IFERROR(MATCH($H40,$H$135:$H$141,1),0)+1)) -> 0 | K40: =E40+F40+I40+G40+J40 -> 0 | L40: No submission
A41: 林志勳 | B41: 半導體碩 / CST | C41: 312591041 | D41: ✓ | E41: =IF(ISBLANK($D41),0,30-VLOOKUP($D41, $D$133:$E$149, 2, FALSE)) -> 30 | F41: 30 | G41: 21 | H41: 3.089 | I41: =IF(ISBLANK($H41),0,INDEX({10,8.75,7.5,6.25,5,3.75,2.5,1.25},IFERROR(MATCH($H41,$H$135:$H$141,1),0)+1)) -> 5 | K41: =E41+F41+I41+G41+J41 -> 86
...

Sheet Lab03
A1: 姓名 | B1: 所屬系所 | C1: 學號 | D1: Model size (kB) | E1: Validation BLEU score | I1: Execution time (s) | J1: Requirement | M1: Testing BLEU score | Q1: Task (60%) | R1: Performance (20%) | S1: Report (20%) | T1: Naming Error | U1: Total | V1: Note
E2: 1-gram | F2: 2-gram | G2: 3-gram | H2: 4-gram | J2: Model Size | K2: BLEU score | L2: Exe time | M2: 1-gram | N2: 2-gram | O2: 3-gram | P2: 4-gram
A3: 林知翰 | B3: 土木系 / DCV | C3: 0811254 | D3: 29846.15 | E3: 0.354085 | F3: 0.20974 | G3: 0.130745 | H3: 0.089661 | I3: 1.865 | J3: PASS | K3: PASS | L3: PASS | M3: 0.395073 | N3: 0.264856 | O3: 0.173215 | P3: 0.112622 | Q3: 60 | R3: =IF($M3=0,0,20-INDEX({0,1,2,3,4,5,6,7,8,9,10,11,12,13,14,15,16,17,18,19,20},IFERROR(MATCH($M3,$D$136:$D$156,-1),0)+1)) -> 4 | S3: 17 | U3: =Q3+R3+S3+T3 -> 81
A4: 林品妤 | B4: 醫工系 / BME | C4: 111261022 | D4: 0 | E4: 0 | F4: 0 | G4: 0 | H4: 0 | I4: 0 | J4: FAIL | K4: FAIL | L4: FAIL | M4: 0 | N4: 0 | O4: 0 | P4: 0 | Q4: 0 | R4: =IF($M4=0,0,20-INDEX({0,1,2,3,4,5,6,7,8,9,10,11,12,13,14,15,16,17,18,19,20},IFERROR(MATCH($M4,$D$136:$D$156,-1),0)+1)) -> 0 | S4: 0 | U4: =Q4+R4+S4+T4 -> 0 | V4: No submission
A5: 趙立榆 | B5: 電機系 / UEE | C5: 111511003 | D5: 0 | E5: 0 | F5: 0 | G5: 0 | H5: 0 | I5: 0 | J5: FAIL | K5: FAIL | L5: FAIL | M5: 0 | N5: 0 | O5: 0 | P5: 0 | Q5: 0 | R5: =IF($M5=0,0,20-INDEX({0,1,2,3,4,5,6,7,8,9,10,11,12,13,14,15,16,17,18,19,20},IFERROR(MATCH($M5,$D$136:$D$156,-1),0)+1)) -> 0 | S5: 0 | U5: =Q5+R5+S5+T5 -> 0 | V5: No submission
A6: 劉邦榆 | B6: 電機系 / UEE | C6: 111511005 | D6: 0 | E6: 0 | F6: 0 | G6: 0 | H6: 0 | I6: 0 | J6: FAIL | K6: FAIL | L6: FAIL | M6: 0 | N6: 0 | O6: 0 | P6: 0 | Q6: 0 | R6: =IF($M6=0,0,20-INDEX({0,1,2,3,4,5,6,7,8,9,10,11,12,13,14,15,16,17,18,19,20},IFERROR(MATCH($M6,$D$136:$D$156,-1),0)+1)) -> 0 | S6: 0 | U6: =Q6+R6+S6+T6 -> 0 | V6: No submission
A7: 林后辰 | B7: 電機系 / UEE | C7: 111511009 | D7: 35840.84 | E7: 0.485391 | F7: 0.33466 | G7: 0.234108 | H7: 0.153467 | I7: 7.582 | J7: PASS | K7: PASS | L7: PASS | M7: 0.504956 | N7: 0.371968 | O7: 0.267121 | P7: 0.170453 | Q7: 60 | R7: =IF($M7=0,0,20-INDEX({0,1,2,3,4,5,6,7,8,9,10,11,12,13,14,15,16,17,18,19,20},IFERROR(MATCH($M7,$D$136:$D$156,-1),0)+1)) -> 16 | S7: 14 | U7: =Q7+R7+S7+T7 -> 90
A8: 莊之睿 | B8: 電機系 / UEE | C8: 111511010 | D8: 78380.36 | E8: 0.388955 | F8: 0.246198 | G8: 0.155328 | H8: 0.110092 | I8: 5.158 | J8: PASS | K8: PASS | L8: PASS | M8: 0.46262 | N8: 0.328848 | O8: 0.224225 | P8: 0.170445 | Q8: 60 | R8: =IF($M8=0,0,20-INDEX({0,1,2,3,4,5,6,7,8,9,10,11,12,13,14,15,16,17,18,19,20},IFERROR(MATCH($M8,$D$136:$D$156,-1),0)+1)) -> 9 | S8: 15 | U8: =Q8+R8+S8+T8 -> 84
A9: 郭弋愷 | B9: 電機系 / UEE | C9: 111511057 | D9: 12338.63 | E9: 0.383751 | F9: 0.244701 | G9: 0.161666 | H9: 0.109468 | I9: 3.798 | J9: PASS | K9: PASS | L9: PASS | M9: 0.423175 | N9: 0.284036 | O9: 0.195537 | P9: 0.132642 | Q9: 60 | R9: =IF($M9=0,0,20-INDEX({0,1,2,3,4,5,6,7,8,9,10,11,12,13,14,15,16,17,18,19,20},IFERROR(MATCH($M9,$D$136:$D$156,-1),0)+1)) -> 6 | S9: 19 | U9: =Q9+R9+S9+T9 -> 85
A10: 茆鎮育 | B10: 電機系 / UEE | C10: 111511059 | D10: 0 | E10: 0 | F10: 0 | G10: 0 | H10: 0 | I10: 0 | J10: FAIL | K10: FAIL | L10: FAIL | M10: 0 | N10: 0 | O10: 0 | P10: 0 | Q10: 0 | R10: =IF($M10=0,0,20-INDEX({0,1,2,3,4,5,6,7,8,9,10,11,12,13,14,15,16,17,18,19,20},IFERROR(MATCH($M10,$D$136:$D$156,-1),0)+1)) -> 0 | S10: 0 | U10: =Q10+R10+S10+T10 -> 0 | V10: No submission
A11: 簡宗弘 | B11: 電機系 / UEE | C11: 111511093 | D11: 28709.96 | E11: 0.471515 | F11: 0.338788 | G11: 0.236714 | H11: 0.16598 | I11: 20.951 | J11: PASS | K11: PASS | L11: PASS | M11: 0.515201 | N11: 0.390445 | O11: 0.291606 | P11: 0.216779 | Q11: 60 | R11: =IF($M11=0,0,20-INDEX({0,1,2,3,4,5,6,7,8,9,10,11,12,13,14,15,16,17,18,19,20},IFERROR(MATCH($M11,$D$136:$D$156,-1),0)+1)) -> 18 | S11: 17 | U11: =Q11+R11+S11+T11 -> 95
A12: 林守凡 | B12: 電機系 / UEE | C12: 111511095 | D12: 23970.12 | E12: 0.361975 | F12: 0.222668 | G12: 0.143948 | H12: 0.089755 | I12: 2.213 | J12: PASS | K12: PASS | L12: PASS | M12: 0.389446 | N12: 0.253187 | O12: 0.159237 | P12: 0.106518 | Q12: 60 | R12: =IF($M12=0,0,20-INDEX({0,1,2,3,4,5,6,7,8,9,10,11,12,13,14,15,16,17,18,19,20},IFERROR(MATCH($M12,$D$136:$D$156,-1),0)+1)) -> 4 | S12: 14 | U12: =Q12+R12+S12+T12 -> 78
A13: 陳禹丞 | B13: 電機系 / UEE | C13: 111511099 | D13: 27656.52 | E13: 0.416882 | F13: 0.284867 | G13: 0.199553 | H13: 0.136759 | I13: 28.791 | J13: PASS | K13: PASS | L13: PASS | M13: 0.468202 | N13: 0.33883 | O13: 0.235985 | P13: 0.155629 | Q13: 60 | R13: =IF($M13=0,0,20-INDEX({0,1,2,3,4,5,6,7,8,9,10,11,12,13,14,15,16,17,18,19,20},IFERROR(MATCH($M13,$D$136:$D$156,-1),0)+1)) -> 9 | S13: 18 | U13: =Q13+R13+S13+T13 -> 87
A14: 陳郡佑 | B14: 電機系 / UEE | C14: 111511158 | D14: 30826.82 | E14: 0.36978 | F14: 0.232905 | G14: 0.148659 | H14: 0.098145 | I14: 69.838 | J14: PASS | K14: PASS | L14: PASS | M14: 0.411215 | N14: 0.282552 | O14: 0.190834 | P14: 0.126829 | Q14: 60 | R14: =IF($M14=0,0,20-INDEX({0,1,2,3,4,5,6,7,8,9,10,11,12,13,14,15,16,17,18,19,20},IFERROR(MATCH($M14,$D$136:$D$156,-1),0)+1)) -> 5 | S14: 20 | U14: =Q14+R14+S14+T14 -> 85
A15: 劉哲丞 | B15: 電機系 / UEE | C15: 111511163 | D15: 69964.1 | E15: 0.398362 | F15: 0.252432 | G15: 0.173034 | H15: 0.116574 | I15: 3.167 | J15: PASS | K15: PASS | L15: PASS | M15: 0.449249 | N15: 0.309819 | O15: 0.220229 | P15: 0.157906 | Q15: 60 | R15: =IF($M15=0,0,20-INDEX({0,1,2,3,4,5,6,7,8,9,10,11,12,13,14,15,16,17,18,19,20},IFERROR(MATCH($M15,$D$136:$D$156,-1),0)+1)) -> 8 | S15: 19 | U15: =Q15+R15+S15+T15 -> 87
A16: 鍾宗揚 | B16: 電機系 / UEE | C16: 111511186 | D16: 84678.98 | E16: 0.460445 | F16: 0.321472 | G16: 0.231665 | H16: 0.146852 | I16: 26.458 | J16: PASS | K16: PASS | L16: PASS | M16: 0.511257 | N16: 0.38133 | O16: 0.279452 | P16: 0.202858 | Q16: 60 | R16: =IF($M16=0,0,20-INDEX({0,1,2,3,4,5,6,7,8,9,10,11,12,13,14,15,16,17,18,19,20},IFERROR(MATCH($M16,$D$136:$D$156,-1),0)+1)) -> 18 | S16: 17 | U16: =Q16+R16+S16+T16 -> 95
A17: 林文遠 | B17: 電機系 / UEE | C17: 111511208 | D17: 19552 | E17: 0.453335 | F17: 0.32024 | G17: 0.227677 | H17: 0.153362 | I17: 40.726 | J17: PASS | K17: PASS | L17: PASS | M17: 0.496855 | N17: 0.366111 | O17: 0.245556 | P17: 0.168119 | Q17: 60 | R17: =IF($M17=0,0,20-INDEX({0,1,2,3,4,5,6,7,8,9,10,11,12,13,14,15,16,17,18,19,20},IFERROR(MATCH($M17,$D$136:$D$156,-1),0)+1)) -> 15 | S17: 17 | U17: =Q17+R17+S17+T17 -> 92
A18: 賴柏任 | B18: 電機系 / UEE | C18: 111511211 | D18: 23441.22 | E18: 0.458585 | F18: 0.318164 | G18: 0.239043 | H18: 0.168116 | I18: 2.948 | J18: PASS | K18: PASS | L18: PASS | M18: 0.488979 | N18: 0.366059 | O18: 0.275914 | P18: 0.208694 | Q18: 60 | R18: =IF($M18=0,0,20-INDEX({0,1,2,3,4,5,6,7,8,9,10,11,12,13,14,15,16,17,18,19,20},IFERROR(MATCH($M18,$D$136:$D$156,-1),0)+1)) -> 13 | S18: 15 | U18: =Q18+R18+S18+T18 -> 88
A19: 王乙棠 | B19: 電機系 / UEE | C19: 111511240 | D19: 82426.18 | E19: 0.451019 | F19: 0.307303 | G19: 0.22452 | H19: 0.156869 | I19: 29.752 | J19: PASS | K19: PASS | L19: PASS | M19: 0.483455 | N19: 0.351722 | O19: 0.26478 | P19: 0.181837 | Q19: 60 | R19: =IF($M19=0,0,20-INDEX({0,1,2,3,4,5,6,7,8,9,10,11,12,13,14,15,16,17,18,19,20},IFERROR(MATCH($M19,$D$136:$D$156,-1),0)+1)) -> 12 | S19: 17 | U19: =Q19+R19+S19+T19 -> 89
A20: 李宇翔 | B20: 電機系 / UEE | C20: 111511247 | D20: 12001.6 | E20: 0.426016 | F20: 0.285927 | G20: 0.201969 | H20: 0.146243 | I20: 3.63 | J20: PASS | K20: PASS | L20: PASS | M20: 0.479578 | N20: 0.343013 | O20: 0.244833 | P20: 0.174928 | Q20: 60 | R20: =IF($M20=0,0,20-INDEX({0,1,2,3,4,5,6,7,8,9,10,11,12,13,14,15,16,17,18,19,20},IFERROR(MATCH($M20,$D$136:$D$156,-1),0)+1)) -> 11 | S20: 15 | U20: =Q20+R20+S20+T20 -> 86
A21: 李昱承 | B21: 電機系 / UEE | C21: 111511249 | D21: 8635.392 | E21: 0.480267 | F21: 0.346125 | G21: 0.246424 | H21: 0.184502 | I21: 4.299 | J21: PASS | K21: PASS | L21: PASS | M21: 0.512923 | N21: 0.393315 | O21: 0.295837 | P21: 0.224153 | Q21: 60 | R21: =IF($M21=0,0,20-INDEX({0,1,2,3,4,5,6,7,8,9,10,11,12,13,14,15,16,17,18,19,20},IFERROR(MATCH($M21,$D$136:$D$156,-1),0)+1)) -> 18 | S21: 17 | U21: =Q21+R21+S21+T21 -> 95
A22: 鄭丞佑 | B22: 電機系 / UEE | C22: 111511253 | D22: 35811.84 | E22: 0.398458 | F22: 0.256001 | G22: 0.166595 | H22: 0.117504 | I22: 4.28 | J22: PASS | K22: PASS | L22: PASS | M22: 0.439171 | N22: 0.302634 | O22: 0.201906 | P22: 0.123875 | Q22: 60 | R22: =IF($M22=0,0,20-INDEX({0,1,2,3,4,5,6,7,8,9,10,11,12,13,14,15,16,17,18,19,20},IFERROR(MATCH($M22,$D$136:$D$156,-1),0)+1)) -> 7 | S22: 15 | T22: -5 | U22: =Q22+R22+S22+T22 -> 77
A23: 王信諺 | B23: 電機系 / UEE | C23: 111511260 | D23: 26067.78 | E23: 0.387126 | F23: 0.243842 | G23: 0.15522 | H23: 0.097319 | I23: 2.811 | J23: PASS | K23: PASS | L23: PASS | M23: 0.407483 | N23: 0.276345 | O23: 0.198458 | P23: 0.139938 | Q23: 60 | R23: =IF($M23=0,0,20-INDEX({0,1,2,3,4,5,6,7,8,9,10,11,12,13,14,15,16,17,18,19,20},IFERROR(MATCH($M23,$D$136:$D$156,-1),0)+1)) -> 4 | S23: 16 | U23: =Q23+R23+S23+T23 -> 80
A24: 洪偉軒 | B24: 電機系 / UEE | C24: 111511263 | D24: 96233.54 | E24: 0.444454 | F24: 0.293535 | G24: 0.216564 | H24: 0.142241 | I24: 3.586 | J24: PASS | K24: PASS | L24: PASS | M24: 0.486227 | N24: 0.348472 | O24: 0.24541 | P24: 0.164955 | Q24: 60 | R24: =IF($M24=0,0,20-INDEX({0,1,2,3,4,5,6,7,8,9,10,11,12,13,14,15,16,17,18,19,20},IFERROR(MATCH($M24,$D$136:$D$156,-1),0)+1)) -> 13 | S24: 15 | U24: =Q24+R24+S24+T24 -> 88
A25: 陳沿霖 | B25: 電機系 / UEE | C25: 111511273 | D25: 62607.68 | E25: 0.375564 | F25: 0.239264 | G25: 0.15444 | H25: 0.102211 | I25: 3.991 | J25: PASS | K25: PASS | L25: PASS | M25: 0.370875 | N25: 0.245178 | O25: 0.1523 | P25: 0.103892 | Q25: 60 | R25: =IF($M25=0,0,20-INDEX({0,1,2,3,4,5,6,7,8,9,10,11,12,13,14,15,16,17,18,19,20},IFERROR(MATCH($M25,$D$136:$D$156,-1),0)+1)) -> 3 | S25: 14 | U25: =Q25+R25+S25+T25 -> 77
A26: 黃治鈞 | B26: 電機系 / UEE | C26: 111511306 | D26: 27644.23 | E26: 0.418261 | F26: 0.277565 | G26: 0.194597 | H26: 0.129901 | I26: 4.648 | J26: PASS | K26: PASS | L26: PASS | M26: 0.471821 | N26: 0.337834 | O26: 0.242521 | P26: 0.171008 | Q26: 60 | R26: =IF($M26=0,0,20-INDEX({0,1,2,3,4,5,6,7,8,9,10,11,12,13,14,15,16,17,18,19,20},IFERROR(MATCH($M26,$D$136:$D$156,-1),0)+1)) -> 10 | S26: 15 | U26: =Q26+R26+S26+T26 -> 85
A27: 唐以理 | B27: 電機系 / UEE | C27: 111511307 | D27: 27656.52 | E27: 0.320358 | F27: 0.195835 | G27: 0.13543 | H27: 0.081031 | I27: 5.457 | J27: PASS | K27: PASS | L27: PASS | M27: 0.337235 | N27: 0.207828 | O27: 0.130282 | P27: 0.089334 | Q27: 60 | R27: =IF($M27=0,0,20-INDEX({0,1,2,3,4,5,6,7,8,9,10,11,12,13,14,15,16,17,18,19,20},IFERROR(MATCH($M27,$D$136:$D$156,-1),0)+1)) -> 2 | S27: 15 | U27: =Q27+R27+S27+T27 -> 77
A28: 陳奕廷 | B28: 電機系 / UEE | C28: 111511308 | D28: 33980.74 | E28: 0.455951 | F28: 0.319799 | G28: 0.233043 | H28: 0.163578 | I28: 12.866 | J28: PASS | K28: PASS | L28: PASS | M28: 0.493555 | N28: 0.36399 | O28: 0.264873 | P28: 0.194213 | Q28: =60*0.7 -> 42 | R28: =IF($M28=0,0,20-INDEX({0,1,2,3,4,5,6,7,8,9,10,11,12,13,14,15,16,17,18,19,20},IFERROR(MATCH($M28,$D$136:$D$156,-1),0)+1)) -> 14 | S28: 18 | U28: =Q28+R28+S28+T28 -> 74 | V28: 補交
A29: 薛天其 | B29: 電機系 / UEE | C29: 111610032 | D29: 55251.27 | E29: 0.459334 | F29: 0.318691 | G29: 0.239916 | H29: 0.175806 | I29: 3.039 | J29: PASS | K29: PASS | L29: PASS | M29: 0.507522 | N29: 0.373376 | O29: 0.280161 | P29: 0.194271 | Q29: 60 | R29: =IF($M29=0,0,20-INDEX({0,1,2,3,4,5,6,7,8,9,10,11,12,13,14,15,16,17,18,19,20},IFERROR(MATCH($M29,$D$136:$D$156,-1),0)+1)) -> 17 | S29: 16 | U29: =Q29+R29+S29+T29 -> 93
